Workbook

Sheet 조사개요
B2: 조사명: | C2: 퍼시스_직장인 사무 환경 조사 _최종본_23.10
B4: 기본 개요
B5: 응답 시작 | C5: 2023년 10월 11일 오후 7시 5분 23초
B6: 응답 종료 | C6: 2023년 10월 17일 오후 2시 9분 5초
B7: 문항 수 | C7: 97 문항
B8: 응답 수 | C8: 1000
B9: 표본 오차 | C9: ±2.03%P *(80% 신뢰수준)
B10: 데이터 수집 방법 | C10: 오픈서베이 패널 (모바일 애플리케이션을 통한 응답 수집) * 오픈서베이는 표집 상의 비율 할당 여부에 따라 단순임의추출 또는 층화임의추출 방식을 활용합니다.
B11: 웹 결과 | C11: =HYPERLINK("https://openanalytics.opensurvey.co.kr/surveys/223708?shareKey=bJbhN7yVzESm&lang=ko", "바로 가기")
B12: * 웹결과의 공유키가 만료상태이면 파일을 다시 다운로드 받아주세요

Sheet 목차(Contents)
B2: 목차(Contents)
B4: 번호 | C4: 문항 유형 | D4: 문항 정보 | E4: 이동
B5: sex | C5: 객관식 단일 | D5: 성별 | E5: =HYPERLINK("#"&"'교차분석표(Cross Table)'!B"&MATCH(B5,'교차분석표(Cross Table)'!B:B,0),"Go") -> 0
B6: age | C6: 주관식 숫자 | D6: 나이 | E6: =HYPERLINK("#"&"'교차분석표(Cross Table)'!B"&MATCH(B6,'교차분석표(Cross Table)'!B:B,0),"Go") -> 0
B7: age_10 | C7: 객관식 단일 | D7: 나이(10세 단위) | E7: =HYPERLINK("#"&"'교차분석표(Cross Table)'!B"&MATCH(B7,'교차분석표(Cross Table)'!B:B,0),"Go") -> 0
B8: age_5 | C8: 객관식 단일 | D8: 나이(5세 단위) | E8: =HYPERLINK("#"&"'교차분석표(Cross Table)'!B"&MATCH(B8,'교차분석표(Cross Table)'!B:B,0),"Go") -> 0
B9: area | C9: 객관식 단일 | D9: 지역 | E9: =HYPERLINK("#"&"'교차분석표(Cross Table)'!B"&MATCH(B9,'교차분석표(Cross Table)'!B:B,0),"Go") -> 0
B10: area_group | C10: 객관식 단일 | D10: 지역그룹 | E10: =HYPERLINK("#"&"'교차분석표(Cross Table)'!B"&MATCH(B10,'교차분석표(Cross Table)'!B:B,0),"Go") -> 0
B11: life_style_age | C11: 객관식 단일 | D11: 라이프스타일 나이 | E11: =HYPERLINK("#"&"'교차분석표(Cross Table)'!B"&MATCH(B11,'교차분석표(Cross Table)'!B:B,0),"Go") -> 0
B12: area_capital | C12: 객관식 단일 | D12: 수도권/비수도권 | E12: =HYPERLINK("#"&"'교차분석표(Cross Table)'!B"&MATCH(B12,'교차분석표(Cross Table)'!B:B,0),"Go") -> 0
B13: sex_age_10 | C13: 객관식 단일 | D13: 성별 x 나이(10세) | E13: =HYPERLINK("#"&"'교차분석표(Cross Table)'!B"&MATCH(B13,'교차분석표(Cross Table)'!B:B,0),"Go") -> 0
B14: sex_age_5 | C14: 객관식 단일 | D14: 성별 x 나이(5세) | E14: =HYPERLINK("#"&"'교차분석표(Cross Table)'!B"&MATCH(B14,'교차분석표(Cross Table)'!B:B,0),"Go") -> 0
B15: sex_life_style_age | C15: 객관식 단일 | D15: 성별 x 라이프스타일 나이 | E15: =HYPERLINK("#"&"'교차분석표(Cross Table)'!B"&MATCH(B15,'교차분석표(Cross Table)'!B:B,0),"Go") -> 0
B16: Q1 | C16: 객관식 단일 | D16: 지금부터 패널 분들께 직장 내/외 사무환경에 대한 질문을 드릴 예정입니다. 먼저 문화적 환경의 세부 내용 중 ‘제도적 장치’에 관해 질문을 드리겠습니다. 질문을 잘 읽고 응답해주시기 바랍니다. | E16: =HYPERLINK("#"&"'교차분석표(Cross Table)'!B"&MATCH(B16,'교차분석표(Cross Table)'!B:B,0),"Go") -> 0
... B112: NQ4 | C112: 주관식 숫자 | D112: ‘오피스 외 다른 곳에서 일하는 원격근무’가 가능할 때, 오피스 출근일은 일주일에 며칠이 적당하다고 생각하시나요? | E112: =HYPERLINK("#"&"'교차분석표(Cross Table)'!B"&MATCH(B112,'교차분석표(Cross Table)'!B:B,0),"Go") -> 0

Sheet 교차분석표(Cross Table)
B3: sex | C3: 성별
C5: 번호 | D5: 답안 | E5: 총 | F5: sex. 성별 | H5: age_10. 나이(10세 단위)
F6: 남 | G6: 여 | H6: 10대 | I6: 20대 | J6: 30대 | K6: 40대 | L6: 50대 | M6: 60대 이상
C7: (단위: %) | D7: 총 응답 수 | E7: 1000 | F7: 500 | G7: 500 | H7: - | I7: 239 | J7: 296 | K7: 265 | L7: 200 | M7: -
C8: 1 | D8: 남 | E8: 50.0 | F8: 100.0 | G8: - | H8: - | I8: 44.4 | J8: 46.6 | K8: 52.5 | L8: 58.5 | M8: -
C9: 2 | D9: 여 | E9: 50.0 | F9: - | G9: 100.0 | H9: - | I9: 55.6 | J9: 53.4 | K9: 47.5 | L9: 41.5 | M9: -
D10: 총합 | E10: 100 | F10: 100 | G10: 100 | H10: - | I10: 100 | J10: 100 | K10: 100 | L10: 100 | M10: -
B13: age | C13: 나이
C15: 답안 | E15: 총 | F15: sex. 성별 | H15: age_10. 나이(10세 단위)
F16: 남 | G16: 여 | H16: 10대 | I16: 20대 | J16: 30대 | K16: 40대 | L16: 50대 | M16: 60대 이상
D17: 총 응답 수 | E17: 1000 | F17: 500 | G17: 500 | H17: - | I17: 239 | J17: 296 | K17: 265 | L17: 200 | M17: -
D18: 평균 | E18: 38.79 | F18: 39.87 | G18: 37.70 | H18: - | I18: 26.95 | J18: 34.40 | K18: 43.63 | L18: 53.00 | M18: -
D19: 표준편차 | E19: 9.5969 | F19: 9.7225 | G19: 9.3545 | H19: - | I19: 1.7578 | J19: 2.7142 | K19: 2.7576 | L19: 2.5401 | M19: -
D20: 최빈값 | E20: 29 | F20: 42 | G20: 29 | H20: - | I20: 29 | J20: 34 | K20: 42 | L20: 51 | M20: -
D21: 중앙값 | E21: 38 | F21: 40 | G21: 36 | H21: - | I21: 27 | J21: 34 | K21: 43 | L21: 52 | M21: -
D22: 최소값 | E22: 20 | F22: 20 | G22: 21 | H22: - | I22: 20 | J22: 30 | K22: 40 | L22: 50 | M22: -
D23: 최대값 | E23: 59 | F23: 59 | G23: 59 | H23: - | I23: 29 | J23: 39 | K23: 49 | L23: 59 | M23: -
D24: Percentile30 | E24: 32 | F24: 33 | G24: 30 | H24: - | I24: 26 | J24: 33 | K24: 42 | L24: 51 | M24: -
D25: Percentile70 | E25: 44 | F25: 46 | G25: 43 | H25: - | I25: 28 | J25: 36 | K25: 45 | L25: 54 | M25: -
B28: age_10 | C28: 나이(10세 단위)
C30: 번호 | D30: 답안 | E30: 총 | F30: sex. 성별 | H30: age_10. 나이(10세 단위)
F31: 남 | G31: 여 | H31: 10대 | I31: 20대 | J31: 30대 | K31: 40대 | L31: 50대 | M31: 60대 이상
C32: (단위: %) | D32: 총 응답 수 | E32: 1000 | F32: 500 | G32: 500 | H32: - | I32: 239 | J32: 296 | K32: 265 | L32: 200 | M32: -
C33: 1 | D33: 10대 | E33: - | F33: - | G33: - | H33: - | I33: - | J33: - | K33: - | L33: - | M33: -
C34: 2 | D34: 20대 | E34: 23.9 | F34: 21.2 | G34: 26.6 | H34: - | I34: 100.0 | J34: - | K34: - | L34: - | M34: -
C35: 3 | D35: 30대 | E35: 29.6 | F35: 27.6 | G35: 31.6 | H35: - | I35: - | J35: 100.0 | K35: - | L35: - | M35: -
C36: 4 | D36: 40대 | E36: 26.5 | F36: 27.8 | G36: 25.2 | H36: - | I36: - | J36: - | K36: 100.0 | L36: - | M36: -
C37: 5 | D37: 50대 | E37: 20.0 | F37: 23.4 | G37: 16.6 | H37: - | I37: - | J37: - | K37: - | L37: 100.0 | M37: -
C38: 6 | D38: 60대 이상 | E38: - | F38: - | G38: - | H38: - | I38: - | J38: - | K38: - | L38: - | M38: -
D39: 총합 | E39: 100 | F39: 100 | G39: 100 | H39: - | I39: 100 | J39: 100 | K39: 100 | L39: 100 | M39: -
B42: age_5 | C42: 나이(5세 단위)
C44: 번호 | D44: 답안 | E44: 총 | F44: sex. 성별 | H44: age_10. 나이(10세 단위)
F45: 남 | G45: 여 | H45: 10대 | I45: 20대 | J45: 30대 | K45: 40대 | L45: 50대 | M45: 60대 이상
C46: (단위: %) | D46: 총 응답 수 | E46: 1000 | F46: 500 | G46: 500 | H46: - | I46: 239 | J46: 296 | K46: 265 | L46: 200 | M46: -
C47: 1 | D47: 10~14세 | E47: - | F47: - | G47: - | H47: - | I47: - | J47: - | K47: - | L47: - | M47: -
C48: 2 | D48: 15~19세 | E48: - | F48: - | G48: - | H48: - | I48: - | J48: - | K48: - | L48: - | M48: -
C49: 3 | D49: 20~24세 | E49: 2.2 | F49: 1.6 | G49: 2.8 | H49: - | I49: 9.2 | J49: - | K49: - | L49: - | M49: -
C50: 4 | D50: 25~29세 | E50: 21.7 | F50: 19.6 | G50: 23.8 | H50: - | I50: 90.8 | J50: - | K50: - | L50: - | M50: -
C51: 5 | D51: 30~34세 | E51: 15.2 | F51: 13.4 | G51: 17.0 | H51: - | I51: - | J51: 51.4 | K51: - | L51: - | M51: -
C52: 6 | D52: 35~39세 | E52: 14.4 | F52: 14.2 | G52: 14.6 | H52: - | I52: - | J52: 48.6 | K52: - | L52: - | M52: -
...

Sheet 응답 내용(Raw Data)
A1: 응답ID | B1: 패널코드 | C1: 응답 시각 | D1: 성별 | E1: 나이 | F1: 나이(10세 단위) | G1: 나이(5세 단위) | H1: 지역 | I1: 지역그룹 | J1: 라이프스타일 나이 | K1: 수도권/비수도권 | L1: 성별 x 나이(10세) | M1: 성별 x 나이(5세) | N1: 성별 x 라이프스타일 나이 | O1: Q1 | P1: Q2 | W1: Q3 | X1: Q4 | Y1: BQ5 | AJ1: BQ6 | AN1: Q7 | AR1: Q8 | AV1: BQ9 | BC1: BQ10 | BH1: Q11 | BI1: Q12 | BJ1: Q13 | BK1: Q14 | BL1: Q15 | BM1: Q16 | BN1: Q17 | BO1: Q18 | BU1: Q19 | BY1: Q20 | CC1: Q21 | CD1: Q22 | CE1: Q23 | CF1: Q24 | CG1: Q25 | CH1: Q26 | CI1: BQ27 | CK1: Q28 | CP1: Q29 | CQ1: Q30 | DB1: Q31 | DL1: Q32 | DM1: Q33 | DN1: Q34 | DO1: Q35 | DP1: Q36 | DQ1: Q37 | DR1: Q38 | DT1: Q39 | DV1: Q40 | EJ1: Q41 | EK1: Q42 | ER1: Q43 | ES1: Q44 | ET1: Q45 | EU1: Q46 | EV1: Q47 | EW1: Q48 | EX1: Q49 | EY1: Q50 | FC1: Q51 | FD1: Q52 | FE1: Q53 | FF1: Q54 | FG1: Q55 | FI1: Q56 | FK1: Q57 | FM1: Q58 | FO1: Q59 | FQ1: Q60 | FR1: Q61 | FT1: Q62 | GB1: Q63 | GZ1: Q64 | HJ1: Q65 | HK1: Q66 | HL1: Q67 | HM1: Q68 | HN1: Q69 | HO1: Q70 | HW1: Q71 | IE1: Q72 | IF1: Q73 | IN1: Q74 | IV1: Q75 | IW1: Q76 | IX1: Q77 | IY1: Q78 | IZ1: Q79 | JA1: Q80 | JB1: Q81 | JC1: Q82 | JD1: Q83 | JE1: Q84 | JF1: Q85 | JG1: Q86 | JH1: SQ1 | JI1: SQ2 | JJ1: SQ3 | JK1: SQ4 | JL1: BSQ5 | JN1: BSQ6 | JP1: BSQ7 | JR1: SQ8 | JS1: SQ9 | JT1: SQ10 | JU1: NQ4
O2: 객관식 단일 | P2: 객관식 중복 | W2: 주관식 숫자 | X2: 객관식 단일 | Y2: 객관식 중복 | AJ2: 객관식 순위 | AN2: 객관식 순위 | AR2: 객관식 순위 | AV2: 객관식 순위 | BC2: 객관식 순위 | BH2: 객관식 단일 | BI2: 객관식 단일 | BJ2: 평가형 5점 | BK2: 평가형 5점 | BL2: 평가형 5점 | BM2: 평가형 5점 | BN2: 평가형 5점 | BO2: 객관식 순위 | BU2: 객관식 순위 | BY2: 객관식 순위 | CC2: 평가형 5점 | CD2: 객관식 척도 | CE2: 주관식 숫자 | CF2: 주관식 숫자 | CG2: 평가형 5점 | CH2: 객관식 단일 | CI2: 객관식 단일 | CK2: 객관식 순위 | CP2: 평가형 5점 | CQ2: 객관식 중복 | DB2: 객관식 중복 | DL2: 객관식 단일 | DM2: 평가형 5점 | DN2: 평가형 5점 | DO2: 평가형 5점 | DP2: 평가형 5점 | DQ2: 객관식 단일 | DR2: 객관식 단일 | DT2: 객관식 단일 | DV2: 객관식 중복 | EJ2: 평가형 5점 | EK2: 객관식 중복 | ER2: 객관식 단일 | ES2: 평가형 5점 | ET2: 평가형 5점 | EU2: 평가형 5점 | EV2: 평가형 5점 | EW2: 객관식 단일 | EX2: 객관식 척도 | EY2: 객관식 순위 | FC2: 평가형 5점 | FD2: 객관식 단일 | FE2: 주관식 숫자 | FF2: 주관식 숫자 | FG2: 객관식 단일 | FI2: 객관식 단일 | FK2: 객관식 단일 | FM2: 객관식 단일 | FO2: 객관식 단일 | FQ2: 객관식 단일 | FR2: 객관식 단일 | FT2: 객관식 중복 | GB2: 객관식 중복 | GZ2: 객관식 중복 | HJ2: 객관식 단일 | HK2: 평가형 5점 | HL2: 평가형 5점 | HM2: 객관식 단일 | HN2: 객관식 단일 | HO2: 객관식 중복 | HW2: 객관식 중복 | IE2: 객관식 단일 | IF2: 객관식 중복 | IN2: 객관식 중복 | IV2: 평가형 5점 | IW2: 객관식 단일 | IX2: 평가형 5점 | IY2: 평가형 5점 | IZ2: 평가형 5점 | JA2: 평가형 5점 | JB2: 평가형 5점 | JC2: 평가형 5점 | JD2: 평가형 5점 | JE2: 평가형 5점 | JF2: 평가형 5점 | JG2: 평가형 5점 | JH2: 객관식 단일 | JI2: 객관식 단일 | JJ2: 객관식 단일 | JK2: 객관식 단일 | JL2: 객관식 단일 | JN2: 객관식 단일 | JP2: 객관식 단일 | JR2: 객관식 단일 | JS2: 객관식 단일 | JT2: 객관식 단일 | JU2: 주관식 숫자
O3: 응답 | P3: 없음 | Q3: 1 | R3: 2 | S3: 3 | T3: 4 | U3: 5 | V3: 기타 의견 | X3: 응답 | Y3: 없음 | Z3: 1 | AA3: 2 | AB3: 3 | AC3: 4 | AD3: 5 | AE3: 6 | AF3: 7 | AG3: 8 | AH3: 9 | AI3: 기타 의견 | AJ3: 1순위 | AK3: 2순위 | AL3: 3순위 | AM3: 기타 의견 | AN3: 1순위 | AO3: 2순위 | AP3: 3순위 | AQ3: 기타 의견 | AR3: 1순위 | AS3: 2순위 | AT3: 3순위 | AU3: 기타 의견 | AV3: 없음 | AW3: 1순위 | AX3: 2순위 | AY3: 3순위 | AZ3: 4순위 | BA3: 5순위 | BB3: 기타 의견 | BC3: 없음 | BD3: 1순위 | BE3: 2순위 | BF3: 3순위 | BG3: 기타 의견 | BH3: 응답 | BI3: 응답 | BO3: 1순위 | BP3: 2순위 | BQ3: 3순위 | BR3: 4순위 | BS3: 5순위 | BT3: 기타 의견 | BU3: 1순위 | BV3: 2순위 | BW3: 3순위 | BX3: 4순위 | BY3: 1순위 | BZ3: 2순위 | CA3: 3순위 | CB3: 4순위 | CH3: 응답 | CI3: 응답 | CJ3: 기타 의견 | CK3: 1순위 | CL3: 2순위 | CM3: 3순위 | CN3: 4순위 | CO3: 5순위 | CQ3: 없음 | CR3: 1 | CS3: 2 | CT3: 3 | CU3: 4 | CV3: 5 | CW3: 6 | CX3: 7 | CY3: 8 | CZ3: 9 | DA3: 기타 의견 | DB3: 1 | DC3: 2 | DD3: 3 | DE3: 4 | DF3: 5 | DG3: 6 | DH3: 7 | DI3: 8 | DJ3: 9 | DK3: 기타 의견 | DL3: 응답 | DQ3: 응답 | DR3: 응답 | DS3: 기타 의견 | DT3: 응답 | DU3: 기타 의견 | DV3: 1 | DW3: 2 | DX3: 3 | DY3: 4 | DZ3: 5 | EA3: 6 | EB3: 7 | EC3: 8 | ED3: 9 | EE3: 10 | EF3: 11 | EG3: 12 | EH3: 13 | EI3: 기타 의견 | EK3: 1 | EL3: 2 | EM3: 3 | EN3: 4 | EO3: 5 | EP3: 6 | EQ3: 기타 의견 | ER3: 응답 | EW3: 응답 | EY3: 1순위 | EZ3: 2순위 | FA3: 3순위 | FB3: 기타 의견 | FD3: 응답 | FG3: 응답 | FH3: 기타 의견 | FI3: 응답 | FJ3: 기타 의견 | FK3: 응답 | FL3: 기타 의견 | FM3: 응답 | FN3: 기타 의견 | FO3: 응답 | FP3: 기타 의견 | FQ3: 응답 | FR3: 응답 | FS3: 기타 의견 | FT3: 없음 | FU3: 1 | FV3: 2 | FW3: 3 | FX3: 4 | FY3: 5 | FZ3: 6 | GA3: 기타 의견 | GB3: 없음 | GC3: 1 | GD3: 2 | GE3: 3 | GF3: 4 | GG3: 5 | GH3: 6 | GI3: 7 | GJ3: 8 | GK3: 9 | GL3: 10 | GM3: 11 | GN3: 12 | GO3: 13 | GP3: 14 | GQ3: 15 | GR3: 16 | GS3: 17 | GT3: 18 | GU3: 19 | GV3: 20 | GW3: 21 | GX3: 22 | GY3: 기타 의견 | GZ3: 없음 | HA3: 1 | HB3: 2 | HC3: 3 | HD3: 4 | HE3: 5 | HF3: 6 | HG3: 7 | HH3: 8 | HI3: 기타 의견 | HJ3: 응답 | HM3: 응답 | HN3: 응답 | HO3: 1 | HP3: 2 | HQ3: 3 | HR3: 4 | HS3: 5 | HT3: 6 | HU3: 7 | HV3: 기타 의견 | HW3: 없음 | HX3: 1 | HY3: 2 | HZ3: 3 | IA3: 4 | IB3: 5 | IC3: 6 | ID3: 기타 의견 | IE3: 응답 | IF3: 1 | IG3: 2 | IH3: 3 | II3: 4 | IJ3: 5 | IK3: 6 | IL3: 7 | IM3: 기타 의견 | IN3: 1 | IO3: 2 | IP3: 3 | IQ3: 4 | IR3: 5 | IS3: 6 | IT3: 7 | IU3: 기타 의견 | IW3: 응답 | JH3: 응답 | JI3: 응답 | JJ3: 응답 | JK3: 응답 | JL3: 응답 | JM3: 기타 의견 | JN3: 응답 | JO3: 기타 의견 | JP3: 응답 | JQ3: 기타 의견 | JR3: 응답 | JS3: 응답 | JT3: 응답
A4: 9ud405e8 | B4: ncbcqtzf | C4: 2023-10-11 19:10:34 | D4: 남 | E4: 37 | F4: 30대 | G4: 35~39세 | H4: 서울 | I4: 서울 | J4: 35~44세 | K4: 수도권 | L4: 남 30대 | M4: 남 35~39세 | N4: 남 35~44세 | O4: 1 | R4: 2 | W4: 40 | X4: 3 | Z4: 1 | AA4: 2 | AE4: 6 | AJ4: 1 | AN4: 1 | AO4: 4 | AP4: 2 | AR4: 1 | AS4: 4 | AT4: 2 | AW4: 2 | AX4: 1 | AY4: 8 | AZ4: 6 | BA4: 5 | BD4: 1 | BE4: 2 | BF4: 6 | BH4: 1 | BI4: 2 | BJ4: 4 | BK4: 3 | BL4: 3 | BM4: 2 | BN4: 3 | BO4: 4 | BP4: 2 | BQ4: 3 | BR4: 1 | BU4: 3 | BY4: 2 | BZ4: 1 | CA4: 3 | CC4: 3 | CD4: 4 | CF4: 30 | CG4: 2 | CH4: 1 | CI4: 5 | CK4: 4 | CP4: 2 | CR4: 1 | CS4: 2 | CT4: 3 | CV4: 5 | DB4: 1 | DI4: 8 | DL4: 2 | DM4: 2 | DN4: 2 | DO4: 2 | DP4: 2 | DQ4: 1 | DR4: 2 | DT4: 1 | DV4: 1 | DW4: 2 | DZ4: 5 | EA4: 6 | EB4: 7 | EC4: 8 | ED4: 9 | EE4: 10 | EF4: 11 | EJ4: 3 | EK4: 1 | ER4: 2 | ES4: 2 | ET4: 2 | EU4: 3 | EV4: 3 | EW4: 3 | EX4: 3 | EY4: 2 | EZ4: 9 | FA4: 1 | FC4: 3 | FD4: 1 | FE4: 25 | FF4: 30 | FG4: 2 | FI4: 2 | FK4: 1 | FM4: 2 | FO4: 3 | FQ4: 1 | FR4: 4 | FU4: 1 | FV4: 2 | FW4: 3 | GE4: 3 | GQ4: 15 | HA4: 1 | HC4: 3 | HE4: 5 | HJ4: 1 | HK4: 4 | HL4: 3 | HM4: 2 | HN4: 1 | HW4: -1 | IV4: 4 | IW4: 1 | IX4: 4 | IY4: 4 | IZ4: 4 | JA4: 3 | JB4: 3 | JC4: 3 | JD4: 3 | JE4: 3 | JF4: 4 | JG4: 3 | JH4: 1 | JI4: 6 | JJ4: 9 | JK4: 2 | JL4: 12 | JM4: 부동산 | JN4: 1 | JP4: 1 | JR4: 2 | JS4: 4 | JT4: 2 | JU4: 2
A5: 84gcm833 | B5: 8ro8rxiw | C5: 2023-10-11 19:08:16 | D5: 남 | E5: 40 | F5: 40대 | G5: 40~44세 | H5: 경기 | I5: 서울 외 수도권 | J5: 35~44세 | K5: 수도권 | L5: 남 40대 | M5: 남 40~44세 | N5: 남 35~44세 | O5: 1 | Q5: 1 | R5: 2 | S5: 3 | W5: 52 | X5: 4 | AA5: 2 | AJ5: 2 | AN5: 1 | AO5: 4 | AP5: 2 | AR5: 1 | AS5: 4 | AT5: 2 | AW5: 5 | AX5: 8 | AY5: 9 | AZ5: 10 | BA5: 2 | BD5: 9 | BE5: 6 | BF5: 1 | BH5: 1 | BI5: 1 | BJ5: 1 | BK5: 4 | BL5: 2 | BM5: 2 | BN5: 2 | BO5: 4 | BU5: 3 | BV5: 2 | BY5: 1 | BZ5: 2 | CC5: 2 | CD5: 4 | CF5: 30 | CG5: 3 | CH5: 1 | CI5: 1 | CK5: 3 | CP5: 2 | CY5: 8 | DJ5: 9 | DK5: 캠페인은 내근직원 위주로 전파됨. | DL5: 2 | DM5: 1 | DN5: 1 | DO5: 1 | DP5: 1 | DQ5: 1 | DR5: 2 | DT5: 1 | DV5: 1 | DW5: 2 | EC5: 8 | EJ5: 1 | EK5: 1 | ER5: 2 | ES5: 1 | ET5: 1 | EU5: 1 | EV5: 1 | EW5: 3 | EX5: 4 | EY5: 1 | EZ5: 3 | FA5: 7 | FC5: 1 | FD5: 1 | FE5: 100 | FF5: 40 | FG5: 2 | FI5: 2 | FK5: 1 | FM5: 1 | FO5: 2 | FQ5: 2 | FR5: 3 | FW5: 3 | GE5: 3 | GN5: 12 | GP5: 14 | HC5: 3 | HD5: 4 | HJ5: 1 | HK5: 4 | HL5: 4 | HM5: 2 | HN5: 1 | HX5: 1 | HY5: 2 | HZ5: 3 | IA5: 4 | IE5: 3 | IF5: 1 | IN5: 1 | IR5: 5 | IV5: 3 | IW5: 1 | IX5: 3 | IY5: 1 | IZ5: 4 | JA5: 2 | JB5: 2 | JC5: 2 | JD5: 1 | JE5: 2 | JF5: 1 | JG5: 1 | JH5: 1 | JI5: 6 | JJ5: 9 | JK5: 5 | JL5: 1 | JN5: 4 | JP5: 1 | JR5: 2 | JS5: 5 | JT5: 4 | JU5: 3
A6: qz86w6ev | B6: qvdo1vyl | C6: 2023-10-11 19:38:49 | D6: 여 | E6: 29 | F6: 20대 | G6: 25~29세 | H6: 부산 | I6: 5대광역시 | J6: 25~34세 | K6: 비수도권 | L6: 여 20대 | M6: 여 25~29세 | N6: 여 25~34세 | O6: 1 | P6: -1 | W6: 40 | X6: 4 | Y6: -1 | AN6: 4 | AO6: 3 | AP6: 2 | AR6: 5 | AS6: 6 | AT6: 3 | AW6: 1 | AX6: 6 | AY6: 10 | AZ6: 16 | BD6: 1 | BE6: 4 | BF6: 7 | BH6: 1 | BI6: 3 | BJ6: 4 | BK6: 3 | BL6: 2 | BM6: 4 | BN6: 5 | BO6: 1 | BP6: 4 | BU6: 1 | BY6: 1 | CC6: 1 | CD6: 1 | CF6: 80 | CG6: 3 | CH6: 1 | CI6: 1 | CK6: 4 | CL6: 3 | CM6: 2 | CN6: 1 | CO6: 5 | CP6: 1 | CV6: 5 | DE6: 4 | DI6: 8 | DL6: 1 | DM6: 1 | DN6: 2 | DO6: 1 | DP6: 2 | DQ6: 1 | DR6: 1 | DT6: 2 | EH6: 13 | EI6: 없음 | EJ6: 1 | EL6: 2 | ER6: 1 | ES6: 2 | ET6: 1 | EU6: 1 | EV6: 1 | EW6: 1 | EX6: 2 | EY6: 6 | EZ6: 3 | FA6: 4 | FC6: 2 | FD6: 1 | FE6: 35 | FF6: 20 | FG6: 1 | FI6: 1 | FK6: 2 | FM6: 2 | FO6: 1 | FQ6: 2 | FR6: 2 | FT6: -1 | GB6: -1 | GZ6: -1 | HJ6: 1 | HK6: 3 | HL6: 4 | HM6: 1 | HN6: 1 | HW6: -1 | IV6: 2 | IW6: 1 | IX6: 1 | IY6: 1 | IZ6: 2 | JA6: 2 | JB6: 2 | JC6: 2 | JD6: 2 | JE6: 2 | JF6: 3 | JG6: 3 | JH6: 1 | JI6: 6 | JJ6: 8 | JK6: 1 | JL6: 12 | JM6: 복지 | JN6: 2 | JP6: 2 | JR6: 3 | JS6: 2 | JT6: 1 | JU6: 3
A7: x2zlk2fu | B7: 69qwwk4k | C7: 2023-10-11 19:06:17 | D7: 남 | E7: 33 | F7: 30대 | G7: 30~34세 | H7: 울산 | I7: 5대광역시 | J7: 25~34세 | K7: 비수도권 | L7: 남 30대 | M7: 남 30~34세 | N7: 남 25~34세 | O7: 1 | Q7: 1 | R7: 2 | S7: 3 | W7: 40 | X7: 5 | Z7: 1 | AA7: 2 | AJ7: 1 | AK7: 2 | AN7: 1 | AO7: 4 | AP7: 5 | AR7: 5 | AS7: 4 | AT7: 1 | AW7: 1 | AX7: 13 | AY7: 16 | BD7: 4 | BE7: 1 | BF7: 6 | BH7: 1 | BI7: 3 | BJ7: 4 | BK7: 4 | BL7: 2 | BM7: 3 | BN7: 3 | BO7: 3 | BP7: 4 | BQ7: 1 | BU7: 2 | BV7: 3 | BW7: 1 | BY7: 1 | BZ7: 2 | CC7: 3 | CD7: 1 | CF7: 80 | CG7: 4 | CH7: 1 | CI7: 2 | CK7: 1 | CL7: 4 | CP7: 4 | CR7: 1 | CT7: 3 | CV7: 5 | DC7: 2 | DD7: 3 | DE7: 4 | DL7: 2 | DM7: 3 | DN7: 4 | DO7: 2 | DP7: 3 | DQ7: 1 | DR7: 2 | DT7: 2 | DW7: 2 | DZ7: 5 | EC7: 8 | ED7: 9 | EJ7: 3 | EK7: 1 | EN7: 4 | ER7: 1 | ES7: 4 | ET7: 3 | EU7: 3 | EV7: 3 | EW7: 3 | EX7: 2 | EY7: 3 | FC7: 3 | FD7: 1 | FE7: 40 | FF7: 20 | FG7: 1 | FI7: 2 | FK7: 2 | FM7: 1 | FO7: 3 | FQ7: 2 | FR7: 2 | FX7: 4 | GK7: 9 | GR7: 16 | HA7: 1 | HE7: 5 | HJ7: 1 | HK7: 3 | HL7: 3 | HM7: 2 | HN7: 1 | HW7: -1 | IV7: 3 | IW7: 1 | IX7: 4 | IY7: 4 | IZ7: 3 | JA7: 3 | JB7: 3 | JC7: 3 | JD7: 3 | JE7: 3 | JF7: 3 | JG7: 3 | JH7: 1 | JI7: 6 | JJ7: 11 | JK7: 2 | JL7: 3 | JN7: 10 | JP7: 1 | JR7: 3 | JS7: 1 | JT7: 1 | JU7: 4
A8: nfqfnani | B8: rp929lu3 | C8: 2023-10-11 19:10:06 | D8: 여 | E8: 55 | F8: 50대 | G8: 55~59세 | H8: 경기 | I8: 서울 외 수도권 | J8: 55~64세 | K8: 수도권 | L8: 여 50대 | M8: 여 55~59세 | N8: 여 55~64세 | O8: 1 | S8: 3 | W8: 40 | X8: 4 | Z8: 1 | AJ8: 1 | AN8: 1 | AO8: 4 | AP8: 5 | AR8: 4 | AS8: 3 | AT8: 5 | AW8: 6 | AX8: 5 | BD8: 1 | BE8: 2 | BF8: 7 | BH8: 1 | BI8: 3 | BJ8: 1 | BK8: 2 | BL8: 2 | BM8: 4 | BN8: 4 | BO8: 1 | BU8: 2 | BY8: 2 | CC8: 1 | CD8: 2 | CF8: 60 | CG8: 4 | CH8: 1 | CI8: 1 | CK8: 4 | CL8: 1 | CP8: 1 | CR8: 1 | CT8: 3 | CV8: 5 | CX8: 7 | DB8: 1 | DL8: 2 | DM8: 2 | DN8: 2 | DO8: 1 | DP8: 2 | DQ8: 1 | DR8: 2 | DT8: 1 | DW8: 2 | DY8: 4 | DZ8: 5 | EC8: 8 | EF8: 11 | EJ8: 2 | EL8: 2 | ER8: 2 | ES8: 3 | ET8: 4 | EU8: 3 | EV8: 4 | EW8: 1 | EX8: 2 | EY8: 1 | EZ8: 3 | FA8: 5 | FC8: 3 | FD8: 1 | FE8: 110 | FF8: 30 | FG8: 1 | FI8: 2 | FK8: 2 | FM8: 1 | FO8: 3 | FQ8: 1 | FR8: 5 | FT8: -1 | GW8: 21 | HA8: 1 | HJ8: 1 | HK8: 4 | HL8: 3 | HM8: 1 | HN8: 1 | HX8: 1 | IE8: 3 | IL8: 7 | IM8: 의견이라도 청취하려는 노력은 있다는 사실 | IR8: 5 | IV8: 2 | IW8: 1 | IX8: 2 | IY8: 2 | IZ8: 4 | JA8: 3 | JB8: 2 | JC8: 2 | JD8: 3 | JE8: 3 | JF8: 3 | JG8: 3 | JH8: 1 | JI8: 6 | JJ8: 9 | JK8: 4 | JL8: 3 | JN8: 7 | JP8: 1 | JR8: 3 | JS8: 6 | JT8: 6 | JU8: 3
A9: 8mr4bx47 | B9: 22u7z1l3 | C9: 2023-10-11 19:05:57 | D9: 남 | E9: 40 | F9: 40대 | G9: 40~44세 | H9: 대구 | I9: 5대광역시 | J9: 35~44세 | K9: 비수도권 | L9: 남 40대 | M9: 남 40~44세 | N9: 남 35~44세 | O9: 1 | S9: 3 | W9: 48 | X9: 4 | AB9: 3 | AJ9: 3 | AN9: 3 | AO9: 4 | AP9: 5 | AR9: 4 | AS9: 5 | AT9: 3 | AW9: 8 | AX9: 6 | BD9: 6 | BE9: 9 | BF9: 2 | BH9: 1 | BI9: 2 | BJ9: 4 | BK9: 4 | BL9: 3 | BM9: 4 | BN9: 3 | BO9: 3 | BP9: 1 | BQ9: 4 | BU9: 2 | BY9: 2 | CC9: 4 | CD9: 2 | CF9: 80 | CG9: 4 | CH9: 1 | CI9: 3 | CK9: 2 | CP9: 4 | CS9: 2 | CW9: 6 | DC9: 2 | DL9: 2 | DM9: 4 | DN9: 4 | DO9: 3 | DP9: 4 | DQ9: 1 | DR9: 3 | DT9: 1 | DZ9: 5 | ED9: 9 | EJ9: 4 | EK9: 1 | EL9: 2 | ER9: 2 | ES9: 4 | ET9: 3 | EU9: 4 | EV9: 3 | EW9: 3 | EX9: 3 | EY9: 3 | EZ9: 5 | FC9: 4 | FD9: 1 | FE9: 45 | FF9: 30 | FG9: 1 | FI9: 1 | FK9: 2 | FM9: 2 | FO9: 1 | FQ9: 2 | FR9: 1 | FU9: 1 | FY9: 5 | GK9: 9 | GO9: 13 | GS9: 17 | HE9: 5 | HJ9: 1 | HK9: 4 | HL9: 3 | HM9: 2 | HN9: 1 | HX9: 1 | HZ9: 3 | IA9: 4 | IE9: 1 | IJ9: 5 | IV9: 3 | IW9: 1 | IX9: 3 | IY9: 4 | IZ9: 3 | JA9: 3 | JB9: 3 | JC9: 4 | JD9: 4 | JE9: 4 | JF9: 3 | JG9: 4 | JH9: 1 | JI9: 6 | JJ9: 6 | JK9: 4 | JL9: 7 | JN9: 10 | JP9: 2 | JR9: 2 | JS9: 3 | JT9: 3 | JU9: 3
A10: qljv2kmd | B10: 2whesem4 | C10: 2023-10-11 19:08:54 | D10: 여 | E10: 42 | F10: 40대 | G10: 40~44세 | H10: 경기 | I10: 서울 외 수도권 | J10: 35~44세 | K10: 수도권 | L10: 여 40대 | M10: 여 40~44세 | N10: 여 35~44세 | O10: 1 | R10: 2 | W10: 40 | X10: 5 | AA10: 2 | AJ10: 2 | AN10: 1 | AO10: 4 | AP10: 2 | AR10: 3 | AS10: 4 | AT10: 2 | AW10: 2 | AX10: 7 | AY10: 4 | BD10: 7 | BE10: 1 | BF10: 4 | BH10: 1 | BI10: 3 | BJ10: 1 | BK10: 1 | BL10: 1 | BM10: 5 | BN10: 5 | BO10: 4 | BU10: 1 | BY10: 2 | CC10: 1 | CD10: 1 | CF10: 40 | CG10: 2 | CH10: 1 | CI10: 3 | CK10: 4 | CP10: 3 | CV10: 5 | DB10: 1 | DL10: 2 | DM10: 3 | DN10: 3 | DO10: 1 | DP10: 1 | DQ10: 1 | DR10: 3 | DT10: 1 | DZ10: 5 | EE10: 10 | EJ10: 1 | EL10: 2 | EN10: 4 | EO10: 5 | ER10: 2 | ES10: 1 | ET10: 1 | EU10: 1 | EV10: 1 | EW10: 1 | EX10: 4 | EY10: 3 | FC10: 1 | FD10: 1 | FE10: 17 | FF10: 20 | FG10: 1 | FI10: 1 | FK10: 2 | FM10: 3 | FO10: 1 | FQ10: 2 | FR10: 1 | FU10: 1 | FV10: 2 | FW10: 3 | FY10: 5 | GN10: 12 | GP10: 14 | GQ10: 15 | GT10: 18 | HA10: 1 | HB10: 2 | HJ10: 1 | HK10: 3 | HL10: 5 | HM10: 1 | HN10: 2 | HO10: 1 | HQ10: 3 | HS10: 5 | HW10: -1 | IV10: 2 | IW10: 1 | IX10: 1 | IY10: 5 | IZ10: 3 | JA10: 2 | JB10: 2 | JC10: 2 | JD10: 2 | JE10: 2 | JF10: 2 | JG10: 1 | JH10: 1 | JI10: 6 | JJ10: 2 | JK10: 2 | JL10: 11 | JN10: 9 | JP10: 4 | JR10: 3 | JS10: 3 | JT10: 3 | JU10: 4
A11: ihlb4fwb | B11: z1lenuo8 | C11: 2023-10-11 20:01:13 | D11: 남 | E11: 26 | F11: 20대 | G11: 25~29세 | H11: 서울 | I11: 서울 | J11: 25~34세 | K11: 수도권 | L11: 남 20대 | M11: 남 25~29세 | N11: 남 25~34세 | O11: 1 | P11: -1 | W11: 41 | X11: 4 | Z11: 1 | AJ11: 1 | AN11: 1 | AR11: 1 | AW11: 9 | AX11: 1 | AY11: 2 | BD11: 4 | BE11: 2 | BF11: 9 | BH11: 1 | BI11: 1 | BJ11: 4 | BK11: 5 | BL11: 2 | BM11: 2 | BN11: 3 | BO11: 3 | BP11: 4 | BQ11: 1 | BR11: 2 | BU11: 2 | BV11: 1 | BY11: 2 | BZ11: 1 | CC11: 4 | CD11: 2 | CF11: 90 | CG11: 4 | CH11: 1 | CI11: 1 | CK11: 4 | CP11: 3 | CR11: 1 | DF11: 5 | DH11: 7 | DI11: 8 | DL11: 1 | DM11: 3 | DN11: 3 | DO11: 3 | DP11: 3 | DQ11: 1 | DR11: 1 | DT11: 2 | EC11: 8 | EJ11: 2 | EL11: 2 | ER11: 2 | ES11: 2 | ET11: 2 | EU11: 1 | EV11: 1 | EW11: 2 | EX11: 1 | EY11: 6 | EZ11: 5 | FA11: 1 | FC11: 2 | FD11: 1 | FE11: 20 | FF11: 15 | FG11: 1 | FI11: 1 | FK11: 1 | FM11: 2 | FO11: 2 | FQ11: 2 | FR11: 3 | FT11: -1 | GB11: -1 | GZ11: -1 | HJ11: 1 | HK11: 4 | HL11: 4 | HM11: 2 | HN11: 1 | HW11: -1 | IV11: 1 | IW11: 1 | IX11: 4 | IY11: 4 | IZ11: 5 | JA11: 2 | JB11: 3 | JC11: 2 | JD11: 4 | JE11: 3 | JF11: 5 | JG11: 4 | JH11: 1 | JI11: 6 | JJ11: 2 | JK11: 1 | JL11: 8 | JN11: 13 | JO11: 정비 | JP11: 2 | JR11: 3 | JS11: 1 | JT11: 1 | JU11: 3
A12: x1b8842t | B12: 80dhbv41 | C12: 2023-10-12 06:56:20 | D12: 여 | E12: 36 | F12: 30대 | G12: 35~39세 | H12: 부산 | I12: 5대광역시 | J12: 35~44세 | K12: 비수도권 | L12: 여 30대 | M12: 여 35~39세 | N12: 여 35~44세 | O12: 1 | P12: -1 | W12: 40 | X12: 3 | Z12: 1 | AJ12: 1 | AN12: 1 | AO12: 4 | AP12: 2 | AR12: 5 | AS12: 3 | AT12: 1 | AW12: 2 | AX12: 7 | AY12: 3 | AZ12: 10 | BA12: 9 | BD12: 7 | BE12: 1 | BF12: 4 | BH12: 1 | BI12: 2 | BJ12: 4 | BK12: 2 | BL12: 2 | BM12: 3 | BN12: 3 | BO12: 4 | BP12: 3 | BQ12: 1 | BU12: 1 | BY12: 2 | CC12: 3 | CD12: 1 | CF12: 70 | CG12: 3 | CH12: 1 | CI12: 1 | CK12: 4 | CL12: 3 | CP12: 3 | CR12: 1 | CV12: 5 | DD12: 3 | DF12: 5 | DG12: 6 | DL12: 1 | DM12: 3 | DN12: 3 | DO12: 4 | DP12: 3 | DQ12: 1 | DR12: 1 | DT12: 2 | DZ12: 5 | EC12: 8 | ED12: 9 | EF12: 11 | EJ12: 3 | EL12: 2 | ER12: 3 | ES12: 3 | ET12: 3 | EU12: 3 | EV12: 3 | EW12: 1 | EX12: 2 | EY12: 2 | EZ12: 9 | FA12: 3 | FC12: 3 | FD12: 1 | FE12: 30 | FF12: 40 | FG12: 1 | FI12: 1 | FK12: 2 | FM12: 2 | FO12: 2 | FQ12: 1 | FR12: 2 | FU12: 1 | FW12: 3 | FX12: 4 | GK12: 9 | HB12: 2 | HE12: 5 | HJ12: 1 | HK12: 4 | HL12: 4 | HM12: 2 | HN12: 2 | HP12: 2 | HS12: 5 | HZ12: 3 | IE12: 1 | IG12: 2 | IV12: 4 | IW12: 1 | IX12: 3 | IY12: 4 | IZ12: 5 | JA12: 4 | JB12: 4 | JC12: 3 | JD12: 4 | JE12: 3 | JF12: 4 | JG12: 4 | JH12: 1 | JI12: 6 | JJ12: 8 | JK12: 1 | JL12: 8 | JN12: 12 | JP12: 2 | JR12: 3 | JS12: 4 | JT12: 1 | JU12: 2
A13: nj3ot6jl | B13: x30cusxi | C13: 2023-10-11 19:31:43 | D13: 여 | E13: 51 | F13: 50대 | G13: 50~54세 | H13: 서울 | I13: 서울 | J13: 45~54세 | K13: 수도권 | L13: 여 50대 | M13: 여 50~54세 | N13: 여 45~54세 | O13: 1 | P13: -1 | W13: 40 | X13: 6 | Z13: 1 | AJ13: 1 | AN13: 1 | AR13: 2 | AS13: 3 | AT13: 1 | AW13: 2 | AX13: 4 | AY13: 9 | BC13: -1 | BH13: 1 | BI13: 3 | BJ13: 4 | BK13: 2 | BL13: 4 | BM13: 3 | BN13: 3 | BO13: 4 | BP13: 2 | BU13: 2 | BY13: 1 | CC13: 4 | CD13: 2 | CF13: 80 | CG13: 4 | CH13: 1 | CI13: 2 | CK13: 4 | CP13: 4 | CT13: 3 | DB13: 1 | DD13: 3 | DL13: 3 | DM13: 4 | DN13: 4 | DO13: 4 | DP13: 4 | DQ13: 1 | DR13: 1 | DT13: 2 | EH13: 13 | EI13: 없음 | EJ13: 3 | EM13: 3 | EN13: 4 | ER13: 2 | ES13: 4 | ET13: 4 | EU13: 4 | EV13: 4 | EW13: 1 | EX13: 3 | EY13: 6 | EZ13: 4 | FC13: 3 | FD13: 1 | FE13: 50 | FF13: 60 | FG13: 1 | FI13: 1 | FK13: 1 | FM13: 1 | FO13: 2 | FQ13: 1 | FR13: 3 | FX13: 4 | FY13: 5 | GB13: -1 | GZ13: -1 | HJ13: 1 | HK13: 3 | HL13: 5 | HM13: 1 | HN13: 2 | HQ13: 3 | HT13: 6 | HW13: -1 | IV13: 3 | IW13: 1 | IX13: 4 | IY13: 3 | IZ13: 5 | JA13: 4 | JB13: 3 | JC13: 3 | JD13: 4 | JE13: 4 | JF13: 5 | JG13: 4 | JH13: 1 | JI13: 6 | JJ13: 9 | JK13: 1 | JL13: 2 | JN13: 5 | JP13: 2 | JR13: 2 | JS13: 6 | JT13: 5 | JU13: 5
A14: z3ug3ihr | B14: rfkwy2zh | C14: 2023-10-11 19:12:42 | D14: 남 | E14: 32 | F14: 30대 | G14: 30~34세 | H14: 서울 | I14: 서울 | J14: 25~34세 | K14: 수도권 | L14: 남 30대 | M14: 남 30~34세 | N14: 남 25~34세 | O14: 1 | R14: 2 | W14: 8 | X14: 3 | Z14: 1 | AJ14: 1 | AN14: 1 | AO14: 4 | AP14: 5 | AR14: 5 | AS14: 3 | AW14: 12 | AX14: 1 | AY14: 9 | AZ14: 10 | BD14: 5 | BE14: 7 | BF14: 3 | BH14: 1 | BI14: 3 | BJ14: 4 | BK14: 4 | BL14: 2 | BM14: 2 | BN14: 4 | BO14: 4 | BP14: 1 | BU14: 1 | BY14: 2 | BZ14: 1 | CC14: 4 | CD14: 1 | CF14: 50 | CG14: 3 | CH14: 1 | CI14: 1 | CK14: 1 | CL14: 4 | CP14: 3 | CT14: 3 | CU14: 4 | CV14: 5 | CY14: 8 | DE14: 4 | DF14: 5 | DI14: 8 | DL14: 2 | DM14: 4 | DN14: 3 | DO14: 4 | DP14: 4 | DQ14: 1 | DR14: 1 | DT14: 2 | DW14: 2 | EC14: 8 | EJ14: 2 | EL14: 2 | EN14: 4 | ER14: 2 | ES14: 4 | ET14: 3 | EU14: 3 | EV14: 3 | EW14: 1 | EX14: 2 | EY14: 7 | EZ14: 9 | FA14: 8 | FC14: 4 | FD14: 1 | FE14: 40 | FF14: 30 | FG14: 1 | FI14: 1 | FK14: 2 | FM14: 2 | FO14: 3 | FQ14: 2 | FR14: 2 | FV14: 2 | FW14: 3 | GQ14: 15 | GW14: 21 | HB14: 2 | HE14: 5 | HJ14: 1 | HK14: 4 | HL14: 4 | HM14: 2 | HN14: 1 | HZ14: 3 | IE14: 3 | IK14: 6 | IN14: 1 | IV14: 4 | IW14: 1 | IX14: 1 | IY14: 3 | IZ14: 4 | JA14: 3 | JB14: 3 | JC14: 3 | JD14: 2 | JE14: 3 | JF14: 4 | JG14: 2 | JH14: 1 | JI14: 6 | JJ14: 2 | JK14: 5 | JL14: 4 | JN14: 6 | JP14: 1 | JR14: 3 | JS14: 3 | JT14: 2 | JU14: 2
A15: nb42jk11 | B15: jobtl65j | C15: 2023-10-11 19:10:07 | D15: 남 | E15: 34 | F15: 30대 | G15: 30~34세 | H15: 인천 | I15: 서울 외 수도권 | J15: 25~34세 | K15: 수도권 | L15: 남 30대 | M15: 남 30~34세 | N15: 남 25~34세 | O15: 1 | R15: 2 | W15: 40 | X15: 2 | Z15: 1 | AA15: 2 | AJ15: 1 | AK15: 2 | AN15: 3 | AO15: 2 | AP15: 1 | AR15: 3 | AS15: 2 | AT15: 1 | AW15: 12 | AX15: 2 | AY15: 9 | BD15: 1 | BE15: 5 | BF15: 3 | BH15: 1 | BI15: 4 | BJ15: 5 | BK15: 1 | BL15: 2 | BM15: 5 | BN15: 1 | BO15: 4 | BP15: 3 | BU15: 1 | BY15: 1 | CC15: 1 | CD15: 1 | CF15: 30 | CG15: 4 | CH15: 1 | CI15: 1 | CK15: 1 | CL15: 2 | CP15: 3 | CT15: 3 | DF15: 5 | DL15: 1 | DM15: 5 | DN15: 4 | DO15: 3 | DP15: 3 | DQ15: 1 | DR15: 4 | DT15: 2 | EC15: 8 | EJ15: 1 | EL15: 2 | EN15: 4 | EO15: 5 | ER15: 3 | ES15: 2 | ET15: 2 | EU15: 1 | EV15: 1 | EW15: 1 | EX15: 3 | EY15: 1 | EZ15: 6 | FA15: 2 | FC15: 3 | FD15: 1 | FE15: 90 | FF15: 30 | FG15: 1 | FI15: 1 | FK15: 2 | FM15: 2 | FO15: 1 | FQ15: 2 | FR15: 1 | FW15: 3 | GB15: -1 | HE15: 5 | HJ15: 1 | HK15: 3 | HL15: 4 | HM15: 2 | HN15: 2 | HQ15: 3 | HW15: -1 | IV15: 3 | IW15: 1 | IX15: 1 | IY15: 2 | IZ15: 4 | JA15: 2 | JB15: 3 | JC15: 1 | JD15: 3 | JE15: 2 | JF15: 3 | JG15: 2 | JH15: 1 | JI15: 6 | JJ15: 9 | JK15: 2 | JL15: 9 | JN15: 12 | JP15: 2 | JR15: 2 | JS15: 3 | JT15: 3 | JU15: 1
A16: jxmqkqe7 | B16: ned4ewc0 | C16: 2023-10-11 19:52:31 | D16: 남 | E16: 37 | F16: 30대 | G16: 35~39세 | H16: 경기 | I16: 서울 외 수도권 | J16: 35~44세 | K16: 수도권 | L16: 남 30대 | M16: 남 35~39세 | N16: 남 35~44세 | O16: 1 | P16: -1 | W16: 40 | X16: 6 | Z16: 1 | AJ16: 1 | AN16: 1 | AO16: 3 | AR16: 3 | AS16: 1 | AT16: 5 | AW16: 13 | AX16: 9 | AY16: 2 | BD16: 10 | BH16: 1 | BI16: 1 | BJ16: 4 | BK16: 4 | BL16: 2 | BM16: 2 | BN16: 3 | BO16: 4 | BP16: 3 | BU16: 2 | BY16: 2 | CC16: 1 | CD16: 1 | CF16: 80 | CG16: 4 | CH16: 1 | CI16: 2 | CK16: 3 | CL16: 4 | CP16: 3 | CV16: 5 | DB16: 1 | DI16: 8 | DL16: 2 | DM16: 4 | DN16: 3 | DO16: 3 | DP16: 3 | DQ16: 1 | DR16: 4 | DT16: 2 | DZ16: 5 | EJ16: 2 | EL16: 2 | EM16: 3 | EN16: 4 | ER16: 1 | ES16: 3 | ET16: 1 | EU16: 1 | EV16: 2 | EW16: 1 | EX16: 4 | EY16: 3 | EZ16: 1 | FA16: 4 | FC16: 3 | FD16: 1 | FE16: 13 | FF16: 15 | FG16: 1 | FI16: 1 | FK16: 1 | FM16: 2 | FO16: 4 | FQ16: 2 | FR16: 1 | FT16: -1 | GB16: -1 | GZ16: -1 | HJ16: 1 | HK16: 4 | HL16: 4 | HM16: 2 | HN16: 2 | HO16: 1 | HR16: 4 | HW16: -1 | IV16: 4 | IW16: 1 | IX16: 1 | IY16: 3 | IZ16: 5 | JA16: 3 | JB16: 3 | JC16: 3 | JD16: 2 | JE16: 2 | JF16: 4 | JG16: 5 | JH16: 1 | JI16: 6 | JJ16: 2 | JK16: 2 | JL16: 11 | JN16: 8 | JP16: 6 | JQ16: 학교 | JR16: 3 | JS16: 4 | JT16: 2 | JU16: 5
A17: 64kxcb19 | B17: ifnx901q | C17: 2023-10-11 19:16:43 | D17: 남 | E17: 42 | F17: 40대 | G17: 40~44세 | H17: 서울 | I17: 서울 | J17: 35~44세 | K17: 수도권 | L17: 남 40대 | M17: 남 40~44세 | N17: 남 35~44세 | O17: 1 | Q17: 1 | R17: 2 | S17: 3 | W17: 8 | X17: 5 | AA17: 2 | AJ17: 2 | AN17: 2 | AO17: 1 | AR17: 2 | AS17: 1 | AW17: 7 | AX17: 2 | BD17: 1 | BE17: 10 | BH17: 1 | BI17: 4 | BJ17: 4 | BK17: 4 | BL17: 2 | BM17: 3 | BN17: 1 | BO17: 3 | BP17: 1 | BU17: 3 | BY17: 1 | CC17: 2 | CD17: 4 | CF17: 50 | CG17: 2 | CH17: 1 | CI17: 1 | CK17: 4 | CL17: 1 | CP17: 3 | CT17: 3 | CW17: 6 | CX17: 7 | DC17: 2 | DD17: 3 | DE17: 4 | DL17: 1 | DM17: 1 | DN17: 2 | DO17: 3 | DP17: 3 | DQ17: 1 | DR17: 3 | DT17: 4 | DY17: 4 | DZ17: 5 | EC17: 8 | EJ17: 4 | EM17: 3 | EN17: 4 | ER17: 2 | ES17: 4 | ET17: 3 | EU17: 4 | EV17: 4 | EW17: 1 | EX17: 3 | EY17: 8 | EZ17: 9 | FA17: 2 | FC17: 4 | FD17: 1 | FE17: 20 | FF17: 30 | FG17: 2 | FI17: 2 | FK17: 3 | FM17: 3 | FO17: 1 | FQ17: 2 | FR17: 2 | FU17: 1 | FV17: 2 | FW17: 3 | FX17: 4 | FY17: 5 | GE17: 3 | GK17: 9 | GM17: 11 | GN17: 12 | GO17: 13 | GP17: 14 | GQ17: 15 | GR17: 16 | GT17: 18 | GU17: 19 | HA17: 1 | HJ17: 1 | HK17: 5 | HL17: 5 | HM17: 2 | HN17: 1 | HX17: 1 | HZ17: 3 | IE17: 3 | II17: 4 | IJ17: 5 | IO17: 2 | IR17: 5 | IS17: 6 | IV17: 3 | IW17: 1 | IX17: 4 | IY17: 3 | IZ17: 5 | JA17: 2 | JB17: 4 | JC17: 4 | JD17: 4 | JE17: 3 | JF17: 2 | JG17: 3 | JH17: 1 | JI17: 6 | JJ17: 9 | JK17: 2 | JL17: 11 | JN17: 2 | JP17: 4 | JR17: 3 | JS17: 4 | JT17: 3 | JU17: 4
A18: jgs8ipxa | B18: ptoh7z55 | C18: 2023-10-11 19:06:09 | D18: 여 | E18: 29 | F18: 20대 | G18: 25~29세 | H18: 경기 | I18: 서울 외 수도권 | J18: 25~34세 | K18: 수도권 | L18: 여 20대 | M18: 여 25~29세 | N18: 여 25~34세 | O18: 1 | P18: -1 | W18: 8 | X18: 4 | Z18: 1 | AJ18: 1 | AN18: 4 | AO18: 5 | AP18: 1 | AR18: 5 | AS18: 6 | AT18: 2 | AW18: 9 | AX18: 5 | AY18: 2 | BD18: 1 | BE18: 3 | BF18: 4 | BH18: 1 | BI18: 4 | BJ18: 1 | BK18: 4 | BL18: 2 | BM18: 4 | BN18: 2 | BO18: 4 | BP18: 1 | BQ18: 3 | BU18: 2 | BY18: 2 | BZ18: 3 | CC18: 2 | CD18: 1 | CF18: 70 | CG18: 2 | CH18: 1 | CI18: 1 | CK18: 1 | CL18: 3 | CP18: 3 | CT18: 3 | CU18: 4 | DC18: 2 | DG18: 6 | DL18: 2 | DM18: 4 | DN18: 2 | DO18: 3 | DP18: 4 | DQ18: 1 | DR18: 2 | DT18: 1 | DW18: 2 | EC18: 8 | EJ18: 3 | EK18: 1 | EL18: 2 | ER18: 3 | ES18: 3 | ET18: 4 | EU18: 3 | EV18: 3 | EW18: 3 | EX18: 4 | EY18: 9 | EZ18: 1 | FA18: 8 | FC18: 4 | FD18: 1 | FE18: 80 | FF18: 40 | FG18: 1 | FI18: 1 | FK18: 2 | FM18: 2 | FO18: 1 | FQ18: 2 | FR18: 2 | FW18: 3 | FX18: 4 | GK18: 9 | GQ18: 15 | HA18: 1 | HJ18: 1 | HK18: 4 | HL18: 4 | HM18: 2 | HN18: 2 | HO18: 1 | HS18: 5 | HW18: -1 | IV18: 2 | IW18: 1 | IX18: 3 | IY18: 2 | IZ18: 3 | JA18: 3 | JB18: 2 | JC18: 3 | JD18: 3 | JE18: 2 | JF18: 3 | JG18: 2 | JH18: 1 | JI18: 6 | JJ18: 9 | JK18: 4 | JL18: 3 | JN18: 7 | JP18: 2 | JR18: 3 | JS18: 2 | JT18: 2 | JU18: 3
A19: c7uj265v | B19: 9rnrx6od | C19: 2023-10-11 19:09:52 | D19: 남 | E19: 57 | F19: 50대 | G19: 55~59세 | H19: 부산 | I19: 5대광역시 | J19: 55~64세 | K19: 비수도권 | L19: 남 50대 | M19: 남 55~59세 | N19: 남 55~64세 | O19: 1 | P19: -1 | W19: 37 | X19: 6 | Z19: 1 | AJ19: 1 | AN19: 1 | AO19: 2 | AR19: 1 | AS19: 2 | AW19: 2 | BD19: 1 | BE19: 5 | BF19: 6 | BH19: 1 | BI19: 1 | BJ19: 2 | BK19: 4 | BL19: 2 | BM19: 2 | BN19: 2 | BO19: 4 | BP19: 3 | BU19: 1 | BY19: 1 | CC19: 3 | CD19: 2 | CF19: 30 | CG19: 3 | CH19: 1 | CI19: 1 | CK19: 4 | CP19: 3 | CT19: 3 | CV19: 5 | DE19: 4 | DG19: 6 | DL19: 2 | DM19: 4 | DN19: 4 | DO19: 4 | DP19: 3 | DQ19: 1 | DR19: 1 | DT19: 2 | DV19: 1 | EJ19: 3 | EL19: 2 | EN19: 4 | ER19: 2 | ES19: 3 | ET19: 4 | EU19: 3 | EV19: 3 | EW19: 1 | EX19: 2 | EY19: 8 | EZ19: 1 | FA19: 4 | FC19: 3 | FD19: 1 | FE19: 30 | FF19: 30 | FG19: 1 | FI19: 1 | FK19: 3 | FM19: 3 | FO19: 3 | FQ19: 2 | FR19: 3 | FU19: 1 | GB19: -1 | GZ19: -1 | HJ19: 1 | HK19: 4 | HL19: 4 | HM19: 1 | HN19: 1 | HW19: -1 | IV19: 3 | IW19: 1 | IX19: 2 | IY19: 2 | IZ19: 3 | JA19: 2 | JB19: 2 | JC19: 2 | JD19: 2 | JE19: 2 | JF19: 3 | JG19: 2 | JH19: 1 | JI19: 6 | JJ19: 8 | JK19: 1 | JL19: 12 | JM19: 아파트 관리사무소 | JN19: 9 | JP19: 2 | JR19: 2 | JS19: 2 | JT19: 2 | JU19: 5
A20: rewu823u | B20: zil8ih4d | C20: 2023-10-11 19:08:27 | D20: 남 | E20: 44 | F20: 40대 | G20: 40~44세 | H20: 서울 | I20: 서울 | J20: 35~44세 | K20: 수도권 | L20: 남 40대 | M20: 남 40~44세 | N20: 남 35~44세 | O20: 1 | S20: 3 | W20: 52 | X20: 5 | Z20: 1 | AA20: 2 | AB20: 3 | AC20: 4 | AJ20: 2 | AK20: 3 | AL20: 1 | AN20: 2 | AO20: 3 | AP20: 1 | AR20: 5 | AS20: 3 | AT20: 1 | AW20: 2 | AX20: 10 | AY20: 9 | AZ20: 7 | BD20: 10 | BE20: 9 | BF20: 7 | BH20: 1 | BI20: 2 | BJ20: 4 | BK20: 4 | BL20: 4 | BM20: 3 | BN20: 2 | BO20: 3 | BP20: 4 | BU20: 2 | BY20: 2 | CC20: 4 | CD20: 2 | CF20: 70 | CG20: 4 | CH20: 1 | CI20: 3 | CK20: 1 | CL20: 4 | CP20: 4 | CS20: 2 | CT20: 3 | CV20: 5 | DC20: 2 | DF20: 5 | DH20: 7 | DL20: 2 | DM20: 4 | DN20: 4 | DO20: 5 | DP20: 4 | DQ20: 1 | DR20: 4 | DT20: 1 | DX20: 3 | EB20: 7 | EJ20: 4 | EK20: 1 | EL20: 2 | EM20: 3 | EN20: 4 | EO20: 5 | ER20: 2 | ES20: 4 | ET20: 4 | EU20: 4 | EV20: 4 | EW20: 3 | EX20: 1 | EY20: 9 | EZ20: 2 | FA20: 6 | FC20: 4 | FD20: 1 | FE20: 50 | FF20: 30 | FG20: 2 | FI20: 2 | FK20: 2 | FM20: 2 | FO20: 2 | FQ20: 2 | FR20: 3 | FU20: 1 | FY20: 5 | GJ20: 8 | GK20: 9 | GL20: 10 | GO20: 13 | GP20: 14 | GS20: 17 | GU20: 19 | HB20: 2 | HC20: 3 | HE20: 5 | HJ20: 1 | HK20: 4 | HL20: 4 | HM20: 2 | HN20: 2 | HR20: 4 | HS20: 5 | HX20: 1 | HY20: 2 | IE20: 3 | IF20: 1 | II20: 4 | IN20: 1 | IS20: 6 | IV20: 4 | IW20: 1 | IX20: 4 | IY20: 4 | IZ20: 3 | JA20: 3 | JB20: 4 | JC20: 4 | JD20: 4 | JE20: 4 | JF20: 4 | JG20: 3 | JH20: 1 | JI20: 6 | JJ20: 9 | JK20: 2 | JL20: 3 | JN20: 12 | JP20: 2 | JR20: 3 | JS20: 4 | JT20: 3 | JU20: 4
A21: 93vpbdch | B21: cjcne84h | C21: 2023-10-11 19:26:00 | D21: 여 | E21: 51 | F21: 50대 | G21: 50~54세 | H21: 서울 | I21: 서울 | J21: 45~54세 | K21: 수도권 | L21: 여 50대 | M21: 여 50~54세 | N21: 여 45~54세 | O21: 1 | Q21: 1 | W21: 8 | X21: 1 | Y21: -1 | AN21: 1 | AO21: 4 | AP21: 5 | AR21: 4 | AS21: 5 | AW21: 10 | BD21: 4 | BE21: 2 | BH21: 1 | BI21: 1 | BJ21: 1 | BK21: 1 | BL21: 1 | BM21: 1 | BN21: 1 | BO21: 4 | BP21: 3 | BU21: 2 | BY21: 2 | CC21: 1 | CD21: 1 | CF21: 90 | CG21: 4 | CH21: 1 | CI21: 1 | CK21: 1 | CP21: 4 | CU21: 4 | CV21: 5 | DD21: 3 | DL21: 2 | DM21: 4 | DN21: 4 | DO21: 4 | DP21: 4 | DQ21: 1 | DR21: 1 | DT21: 2 | DW21: 2 | EJ21: 4 | EL21: 2 | ER21: 2 | ES21: 3 | ET21: 3 | EU21: 3 | EV21: 3 | EW21: 1 | EX21: 1 | EY21: 1 | FC21: 4 | FD21: 1 | FE21: 80 | FF21: 30 | FG21: 1 | FI21: 1 | FK21: 2 | FM21: 2 | FO21: 2 | FQ21: 2 | FR21: 2 | FX21: 4 | FY21: 5 | GB21: -1 | HC21: 3 | HJ21: 1 | HK21: 4 | HL21: 4 | HM21: 2 | HN21: 2 | HT21: 6 | HZ21: 3 | IE21: 1 | IJ21: 5 | IK21: 6 | IV21: 4 | IW21: 1 | IX21: 4 | IY21: 4 | IZ21: 4 | JA21: 4 | JB21: 4 | JC21: 4 | JD21: 4 | JE21: 4 | JF21: 4 | JG21: 4 | JH21: 1 | JI21: 6 | JJ21: 9 | JK21: 4 | JL21: 3 | JN21: 2 | JP21: 1 | JR21: 2 | JS21: 5 | JT21: 4 | JU21: 0
A22: 20m92g96 | B22: 6yo42adg | C22: 2023-10-11 19:09:51 | D22: 남 | E22: 33 | F22: 30대 | G22: 30~34세 | H22: 경기 | I22: 서울 외 수도권 | J22: 25~34세 | K22: 수도권 | L22: 남 30대 | M22: 남 30~34세 | N22: 남 25~34세 | O22: 1 | R22: 2 | W22: 8 | X22: 3 | Z22: 1 | AA22: 2 | AB22: 3 | AF22: 7 | AG22: 8 | AJ22: 1 | AK22: 2 | AL22: 3 | AN22: 2 | AO22: 1 | AP22: 3 | AR22: 2 | AS22: 1 | AT22: 3 | AW22: 9 | AX22: 1 | AY22: 16 | AZ22: 8 | BA22: 15 | BD22: 1 | BE22: 7 | BF22: 3 | BH22: 1 | BI22: 4 | BJ22: 4 | BK22: 2 | BL22: 5 | BM22: 4 | BN22: 4 | BO22: 4 | BP22: 1 | BQ22: 3 | BR22: 2 | BU22: 2 | BY22: 2 | CC22: 5 | CD22: 4 | CE22: 0 | CF22: 30 | CG22: 5 | CH22: 1 | CI22: 5 | CK22: 2 | CL22: 5 | CM22: 4 | CN22: 3 | CO22: 1 | CP22: 4 | CR22: 1 | CT22: 3 | CU22: 4 | CV22: 5 | CX22: 7 | CY22: 8 | DC22: 2 | DH22: 7 | DL22: 2 | DM22: 4 | DN22: 5 | DO22: 4 | DP22: 4 | DQ22: 1 | DR22: 4 | DT22: 4 | ED22: 9 | EJ22: 1 | EK22: 1 | ER22: 2 | ES22: 2 | ET22: 2 | EU22: 3 | EV22: 2 | EW22: 3 | EX22: 2 | EY22: 2 | EZ22: 1 | FA22: 6 | FC22: 3 | FD22: 1 | FE22: 40 | FF22: 60 | FG22: 1 | FI22: 2 | FK22: 2 | FM22: 3 | FO22: 2 | FQ22: 2 | FR22: 1 | FW22: 3 | GB22: -1 | HA22: 1 | HC22: 3 | HE22: 5 | HJ22: 1 | HK22: 4 | HL22: 4 | HM22: 2 | HN22: 1 | HW22: -1 | IV22: 2 | IW22: 1 | IX22: 1 | IY22: 2 | IZ22: 5 | JA22: 4 | JB22: 1 | JC22: 1 | JD22: 4 | JE22: 2 | JF22: 4 | JG22: 3 | JH22: 1 | JI22: 6 | JJ22: 9 | JK22: 2 | JL22: 1 | JN22: 4 | JP22: 2 | JR22: 2 | JS22: 3 | JT22: 2 | JU22: 2
A23: covd0bqd | B23: qjw9y8de | C23: 2023-10-11 19:27:48 | D23: 남 | E23: 44 | F23: 40대 | G23: 40~44세 | H23: 서울 | I23: 서울 | J23: 35~44세 | K23: 수도권 | L23: 남 40대 | M23: 남 40~44세 | N23: 남 35~44세 | O23: 1 | P23: -1 | W23: 40 | X23: 6 | Z23: 1 | AA23: 2 | AJ23: 1 | AN23: 1 | AO23: 2 | AR23: 1 | AS23: 2 | AT23: 5 | AW23: 13 | AX23: 8 | AY23: 9 | AZ23: 1 | BA23: 2 | BC23: -1 | BH23: 1 | BI23: 1 | BJ23: 4 | BK23: 1 | BL23: 2 | BM23: 4 | BN23: 2 | BO23: 4 | BU23: 1 | BY23: 2 | CC23: 3 | CD23: 2 | CF23: 60 | CG23: 3 | CH23: 1 | CI23: 1 | CK23: 4 | CL23: 2 | CP23: 4 | CR23: 1 | CV23: 5 | DB23: 1 | DF23: 5 | DL23: 1 | DM23: 1 | DN23: 4 | DO23: 2 | DP23: 2 | DQ23: 1 | DR23: 1 | DT23: 2 | DY23: 4 | EF23: 11 | EJ23: 2 | EK23: 1 | EN23: 4 | EO23: 5 | ER23: 3 | ES23: 3 | ET23: 3 | EU23: 4 | EV23: 2 | EW23: 1 | EX23: 3 | EY23: 9 | EZ23: 2 | FA23: 5 | FC23: 2 | FD23: 1 | FE23: 60 | FF23: 30 | FG23: 1 | FI23: 1 | FK23: 1 | FM23: 2 | FO23: 1 | FQ23: 2 | FR23: 1 | FU23: 1 | FW23: 3 | GB23: -1 | HC23: 3 | HJ23: 1 | HK23: 5 | HL23: 2 | HM23: 2 | HN23: 1 | HW23: -1 | IV23: 3 | IW23: 1 | IX23: 2 | IY23: 2 | IZ23: 4 | JA23: 3 | JB23: 2 | JC23: 2 | JD23: 3 | JE23: 3 | JF23: 4 | JG23: 2 | JH23: 1 | JI23: 6 | JJ23: 2 | JK23: 1 | JL23: 5 | JN23: 7 | JP23: 2 | JR23: 2 | JS23: 5 | JT23: 5 | JU23: 5
A24: qn5e9pnb | B24: ptzl7tud | C24: 2023-10-11 19:10:21 | D24: 남 | E24: 30 | F24: 30대 | G24: 30~34세 | H24: 서울 | I24: 서울 | J24: 25~34세 | K24: 수도권 | L24: 남 30대 | M24: 남 30~34세 | N24: 남 25~34세 | O24: 1 | P24: -1 | W24: 40 | X24: 3 | Z24: 1 | AJ24: 1 | AN24: 1 | AR24: 1 | AW24: 10 | AX24: 8 | AY24: 6 | BD24: 7 | BE24: 6 | BF24: 3 | BH24: 1 | BI24: 1 | BJ24: 1 | BK24: 4 | BL24: 2 | BM24: 4 | BN24: 2 | BO24: 4 | BP24: 3 | BQ24: 1 | BR24: 2 | BU24: 1 | BY24: 1 | BZ24: 2 | CA24: 3 | CC24: 1 | CD24: 1 | CF24: 10 | CG24: 2 | CH24: 1 | CI24: 1 | CK24: 4 | CL24: 1 | CP24: 2 | CR24: 1 | CV24: 5 | DB24: 1 | DC24: 2 | DG24: 6 | DL24: 2 | DM24: 1 | DN24: 1 | DO24: 1 | DP24: 2 | DQ24: 1 | DR24: 2 | DT24: 2 | EC24: 8 | EJ24: 1 | EK24: 1 | EL24: 2 | ER24: 2 | ES24: 1 | ET24: 1 | EU24: 1 | EV24: 1 | EW24: 3 | EX24: 4 | EY24: 8 | EZ24: 1 | FA24: 3 | FC24: 1 | FD24: 1 | FE24: 15 | FF24: 30 | FG24: 1 | FI24: 1 | FK24: 2 | FM24: 3 | FO24: 3 | FQ24: 2 | FR24: 1 | FT24: -1 | GR24: 16 | HE24: 5 | HJ24: 1 | HK24: 4 | HL24: 4 | HM24: 2 | HN24: 1 | HW24: -1 | IV24: 2 | IW24: 1 | IX24: 4 | IY24: 3 | IZ24: 3 | JA24: 3 | JB24: 3 | JC24: 2 | JD24: 3 | JE24: 2 | JF24: 3 | JG24: 3 | JH24: 1 | JI24: 6 | JJ24: 9 | JK24: 4 | JL24: 1 | JN24: 4 | JP24: 2 | JR24: 3 | JS24: 2 | JT24: 2 | JU24: 2
A25: c5n1uvkc | B25: rmy58xsb | C25: 2023-10-12 06:40:13 | D25: 남 | E25: 34 | F25: 30대 | G25: 30~34세 | H25: 경기 | I25: 서울 외 수도권 | J25: 25~34세 | K25: 수도권 | L25: 남 30대 | M25: 남 30~34세 | N25: 남 25~34세 | O25: 1 | P25: -1 | W25: 40 | X25: 2 | Z25: 1 | AA25: 2 | AJ25: 1 | AN25: 1 | AO25: 2 | AR25: 1 | AS25: 2 | AW25: 9 | AX25: 16 | AY25: 10 | BD25: 6 | BE25: 4 | BF25: 3 | BH25: 1 | BI25: 1 | BJ25: 4 | BK25: 4 | BL25: 2 | BM25: 2 | BN25: 4 | BO25: 4 | BP25: 3 | BU25: 2 | BY25: 2 | BZ25: 1 | CA25: 3 | CC25: 4 | CD25: 3 | CF25: 70 | CG25: 3 | CH25: 1 | CI25: 1 | CK25: 1 | CP25: 3 | CW25: 6 | DD25: 3 | DF25: 5 | DH25: 7 | DL25: 1 | DM25: 2 | DN25: 4 | DO25: 2 | DP25: 2 | DQ25: 1 | DR25: 1 | DT25: 1 | EA25: 6 | EJ25: 4 | EK25: 1 | EN25: 4 | ER25: 2 | ES25: 2 | ET25: 3 | EU25: 2 | EV25: 2 | EW25: 1 | EX25: 2 | EY25: 1 | EZ25: 4 | FC25: 2 | FD25: 1 | FE25: 70 | FF25: 30 | FG25: 1 | FI25: 1 | FK25: 2 | FM25: 2 | FO25: 2 | FQ25: 2 | FR25: 1 | FW25: 3 | GB25: -1 | HE25: 5 | HJ25: 1 | HK25: 4 | HL25: 4 | HM25: 1 | HN25: 1 | HW25: -1 | IV25: 3 | IW25: 1 | IX25: 4 | IY25: 4 | IZ25: 4 | JA25: 4 | JB25: 3 | JC25: 2 | JD25: 2 | JE25: 3 | JF25: 4 | JG25: 4 | JH25: 1 | JI25: 6 | JJ25: 2 | JK25: 1 | JL25: 1 | JN25: 6 | JP25: 2 | JR25: 3 | JS25: 3 | JT25: 3 | JU25: 1
A26: 8diwe4ii | B26: 6yu3r8vd | C26: 2023-10-11 19:11:22 | D26: 남 | E26: 31 | F26: 30대 | G26: 30~34세 | H26: 서울 | I26: 서울 | J26: 25~34세 | K26: 수도권 | L26: 남 30대 | M26: 남 30~34세 | N26: 남 25~34세 | O26: 1 | S26: 3 | W26: 40 | X26: 2 | Y26: -1 | AN26: 1 | AO26: 3 | AR26: 1 | AS26: 3 | AT26: 5 | AW26: 2 | AX26: 8 | AY26: 9 | AZ26: 13 | BA26: 5 | BD26: 1 | BE26: 3 | BF26: 9 | BH26: 1 | BI26: 2 | BJ26: 3 | BK26: 3 | BL26: 2 | BM26: 3 | BN26: 4 | BO26: 1 | BP26: 4 | BU26: 2 | BV26: 3 | BY26: 2 | CC26: 3 | CD26: 3 | CF26: 60 | CG26: 4 | CH26: 1 | CI26: 1 | CK26: 1 | CP26: 4 | CR26: 1 | CU26: 4 | CV26: 5 | DB26: 1 | DE26: 4 | DF26: 5 | DL26: 3 | DM26: 4 | DN26: 4 | DO26: 4 | DP26: 4 | DQ26: 1 | DR26: 4 | DT26: 2 | DW26: 2 | DZ26: 5 | EJ26: 3 | EK26: 1 | ER26: 3 | ES26: 4 | ET26: 4 | EU26: 3 | EV26: 3 | EW26: 1 | EX26: 3 | EY26: 1 | EZ26: 2 | FA26: 3 | FC26: 4 | FD26: 1 | FE26: 60 | FF26: 30 | FG26: 1 | FI26: 1 | FK26: 3 | FM26: 3 | FO26: 1 | FQ26: 2 | FR26: 2 | FU26: 1 | FV26: 2 | FW26: 3 | GJ26: 8 | GK26: 9 | GN26: 12 | GO26: 13 | GQ26: 15 | GT26: 18 | GW26: 21 | HA26: 1 | HB26: 2 | HC26: 3 | HD26: 4 | HE26: 5 | HJ26: 1 | HK26: 4 | HL26: 4 | HM26: 1 | HN26: 2 | HO26: 1 | HR26: 4 | HT26: 6 | HX26: 1 | IE26: 1 | IG26: 2 | II26: 4 | IV26: 4 | IW26: 1 | IX26: 3 | IY26: 4 | IZ26: 5 | JA26: 4 | JB26: 4 | JC26: 4 | JD26: 4 | JE26: 4 | JF26: 4 | JG26: 4 | JH26: 1 | JI26: 6 | JJ26: 9 | JK26: 4 | JL26: 10 | JN26: 9 | JP26: 4 | JR26: 3 | JS26: 1 | JT26: 1 | JU26: 1
A27: jc7c2yvf | B27: 85t52z67 | C27: 2023-10-11 22:46:04 | D27: 남 | E27: 43 | F27: 40대 | G27: 40~44세 | H27: 부산 | I27: 5대광역시 | J27: 35~44세 | K27: 비수도권 | L27: 남 40대 | M27: 남 40~44세 | N27: 남 35~44세 | O27: 1 | P27: -1 | W27: 40 | X27: 3 | Z27: 1 | AA27: 2 | AJ27: 1 | AK27: 2 | AN27: 1 | AO27: 4 | AP27: 5 | AR27: 5 | AS27: 4 | AT27: 1 | AW27: 9 | AX27: 8 | AY27: 10 | AZ27: 4 | BA27: 1 | BD27: 3 | BE27: 6 | BF27: 1 | BH27: 1 | BI27: 3 | BJ27: 5 | BK27: 5 | BL27: 1 | BO27: 4 | BP27: 1 | BQ27: 3 | BU27: 1 | BV27: 2 | BY27: 1 | CC27: 3 | CD27: 1 | CF27: 70 | CG27: 3 | CH27: 1 | CI27: 1 | CK27: 2 | CL27: 3 | CM27: 4 | CP27: 5 | CQ27: -1 | DC27: 2 | DE27: 4 | DL27: 1 | DM27: 3 | DN27: 4 | DO27: 5 | DP27: 2 | DQ27: 1 | DR27: 4 | DT27: 1 | ED27: 9 | EJ27: 5 | EK27: 1 | ER27: 2 | ES27: 3 | ET27: 1 | EU27: 3 | EV27: 3 | EW27: 1 | EX27: 5 | EY27: 3 | EZ27: 4 | FA27: 6 | FC27: 3 | FD27: 1 | FE27: 70 | FF27: 10 | FG27: 1 | FI27: 1 | FK27: 1 | FM27: 2 | FO27: 1 | FQ27: 2 | FR27: 1 | FU27: 1 | FW27: 3 | GQ27: 15 | GR27: 16 | HB27: 2 | HJ27: 1 | HK27: 5 | HL27: 5 | HM27: 2 | HN27: 2 | HP27: 2 | HR27: 4 | HS27: 5 | HW27: -1 | IV27: 3 | IW27: 1 | IX27: 3 | IY27: 5 | IZ27: 5 | JA27: 5 | JB27: 3 | JC27: 4 | JD27: 5 | JE27: 3 | JF27: 5 | JG27: 5 | JH27: 1 | JI27: 6 | JJ27: 8 | JK27: 1 | JL27: 8 | JN27: 7 | JP27: 2 | JR27: 1 | JS27: 5 | JT27: 2 | JU27: 2
A28: iv1uvx3j | B28: 9dirtdm2 | C28: 2023-10-11 20:09:32 | D28: 남 | E28: 42 | F28: 40대 | G28: 40~44세 | H28: 부산 | I28: 5대광역시 | J28: 35~44세 | K28: 비수도권 | L28: 남 40대 | M28: 남 40~44세 | N28: 남 35~44세 | O28: 1 | P28: -1 | W28: 40 | X28: 4 | Y28: -1 | AN28: 1 | AO28: 4 | AP28: 2 | AR28: 3 | AS28: 1 | AW28: 1 | AX28: 2 | BD28: 10 | BE28: 7 | BF28: 6 | BH28: 1 | BI28: 3 | BJ28: 4 | BK28: 3 | BL28: 3 | BM28: 4 | BN28: 2 | BO28: 4 | BP28: 3 | BQ28: 2 | BR28: 1 | BU28: 1 | BY28: 2 | CC28: 3 | CD28: 3 | CF28: 30 | CG28: 4 | CH28: 1 | CI28: 2 | CK28: 4 | CL28: 5 | CM28: 2 | CN28: 3 | CP28: 4 | CT28: 3 | CV28: 5 | CW28: 6 | CY28: 8 | DC28: 2 | DD28: 3 | DH28: 7 | DL28: 1 | DM28: 4 | DN28: 3 | DO28: 4 | DP28: 4 | DQ28: 1 | DR28: 1 | DT28: 2 | EF28: 11 | EJ28: 4 | EO28: 5 | ER28: 1 | ES28: 3 | ET28: 4 | EU28: 3 | EV28: 3 | EW28: 3 | EX28: 3 | EY28: 8 | EZ28: 2 | FC28: 3 | FD28: 1 | FE28: 50 | FF28: 60 | FG28: 3 | FI28: 2 | FK28: 1 | FM28: 1 | FO28: 4 | FQ28: 1 | FR28: 5 | FU28: 1 | GE28: 3 | GG28: 5 | GK28: 9 | GN28: 12 | GQ28: 15 | HC28: 3 | HG28: 7 | HJ28: 1 | HK28: 3 | HL28: 4 | HM28: 2 | HN28: 2 | HP28: 2 | HS28: 5 | HX28: 1 | HY28: 2 | IE28: 3 | IG28: 2 | IH28: 3 | II28: 4 | IN28: 1 | IO28: 2 | IQ28: 4 | IV28: 3 | IW28: 1 | IX28: 4 | IY28: 3 | IZ28: 3 | JA28: 3 | JB28: 4 | JC28: 4 | JD28: 4 | JE28: 4 | JF28: 4 | JG28: 3 | JH28: 1 | JI28: 6 | JJ28: 8 | JK28: 5 | JL28: 3 | JN28: 10 | JP28: 1 | JR28: 3 | JS28: 6 | JT28: 6 | JU28: 3
A29: 6jfq5pta | B29: nymqxric | C29: 2023-10-11 19:05:23 | D29: 여 | E29: 44 | F29: 40대 | G29: 40~44세 | H29: 경기 | I29: 서울 외 수도권 | J29: 35~44세 | K29: 수도권 | L29: 여 40대 | M29: 여 40~44세 | N29: 여 35~44세 | O29: 1 | Q29: 1 | S29: 3 | W29: 40 | X29: 5 | Z29: 1 | AA29: 2 | AD29: 5 | AJ29: 1 | AK29: 2 | AL29: 5 | AN29: 1 | AO29: 2 | AP29: 4 | AR29: 2 | AS29: 1 | AT29: 5 | AW29: 12 | AX29: 13 | AY29: 8 | AZ29: 11 | BA29: 7 | BD29: 3 | BE29: 4 | BF29: 6 | BH29: 1 | BI29: 2 | BJ29: 4 | BK29: 3 | BL29: 3 | BM29: 3 | BN29: 4 | BO29: 4 | BP29: 1 | BQ29: 3 | BU29: 3 | BV29: 2 | BW29: 1 | BY29: 1 | BZ29: 2 | CA29: 3 | CC29: 4 | CD29: 3 | CF29: 70 | CG29: 3 | CH29: 1 | CI29: 1 | CK29: 2 | CL29: 1 | CP29: 3 | CS29: 2 | CT29: 3 | CY29: 8 | DD29: 3 | DG29: 6 | DH29: 7 | DL29: 1 | DM29: 3 | DN29: 3 | DO29: 3 | DP29: 3 | DQ29: 1 | DR29: 4 | DT29: 3 | DW29: 2 | DY29: 4 | DZ29: 5 | EA29: 6 | EJ29: 4 | EK29: 1 | EL29: 2 | EM29: 3 | EN29: 4 | EO29: 5 | ER29: 2 | ES29: 3 | ET29: 3 | EU29: 3 | EV29: 3 | EW29: 2 | EX29: 3 | EY29: 1 | EZ29: 8 | FA29: 2 | FC29: 3 | FD29: 1 | FE29: 50 | FF29: 30 | FG29: 1 | FI29: 1 | FK29: 3 | FM29: 3 | FO29: 2 | FQ29: 2 | FR29: 1 | FU29: 1 | FV29: 2 | FX29: 4 | FY29: 5 | GC29: 1 | GG29: 5 | GK29: 9 | GN29: 12 | GQ29: 15 | GR29: 16 | GW29: 21 | HB29: 2 | HF29: 6 | HJ29: 1 | HK29: 3 | HL29: 4 | HM29: 2 | HN29: 1 | HX29: 1 | IB29: 5 | IE29: 1 | IG29: 2 | II29: 4 | IV29: 4 | IW29: 1 | IX29: 4 | IY29: 3 | IZ29: 3 | JA29: 3 | JB29: 3 | JC29: 3 | JD29: 4 | JE29: 4 | JF29: 3 | JG29: 3 | JH29: 1 | JI29: 6 | JJ29: 2 | JK29: 2 | JL29: 10 | JN29: 4 | JP29: 2 | JR29: 2 | JS29: 5 | JT29: 3 | JU29: 4
A30: foj9fdih | B30: qtmtdqg3 | C30: 2023-10-11 20:53:38 | D30: 여 | E30: 31 | F30: 30대 | G30: 30~34세 | H30: 인천 | I30: 서울 외 수도권 | J30: 25~34세 | K30: 수도권 | L30: 여 30대 | M30: 여 30~34세 | N30: 여 25~34세 | O30: 1 | R30: 2 | W30: 8 | X30: 4 | Z30: 1 | AA30: 2 | AJ30: 1 | AK30: 2 | AN30: 1 | AO30: 5 | AP30: 2 | AR30: 1 | AS30: 2 | AT30: 5 | AW30: 5 | AX30: 8 | AY30: 9 | BD30: 6 | BE30: 1 | BF30: 9 | BH30: 1 | BI30: 2 | BJ30: 4 | BK30: 5 | BL30: 4 | BM30: 4 | BN30: 2 | BO30: 4 | BP30: 1 | BQ30: 3 | BU30: 2 | BY30: 2 | BZ30: 1 | CC30: 3 | CD30: 4 | CF30: 60 | CG30: 4 | CH30: 1 | CI30: 1 | CK30: 3 | CL30: 1 | CP30: 4 | CS30: 2 | CV30: 5 | CW30: 6 | DC30: 2 | DF30: 5 | DL30: 2 | DM30: 4 | DN30: 4 | DO30: 3 | DP30: 4 | DQ30: 1 | DR30: 5 | DS30: 비대면보고 | DT30: 1 | DW30: 2 | DZ30: 5 | EC30: 8 | ED30: 9 | EJ30: 3 | EK30: 1 | EL30: 2 | EN30: 4 | ER30: 2 | ES30: 3 | ET30: 4 | EU30: 3 | EV30: 3 | EW30: 1 | EX30: 2 | EY30: 1 | EZ30: 2 | FC30: 4 | FD30: 1 | FE30: 95 | FF30: 30 | FG30: 1 | FI30: 1 | FK30: 2 | FM30: 2 | FO30: 2 | FQ30: 1 | FR30: 2 | FV30: 2 | FW30: 3 | GK30: 9 | GL30: 10 | GP30: 14 | GQ30: 15 | GT30: 18 | GW30: 21 | HA30: 1 | HC30: 3 | HD30: 4 | HE30: 5 | HF30: 6 | HJ30: 1 | HK30: 4 | HL30: 4 | HM30: 2 | HN30: 2 | HQ30: 3 | HT30: 6 | IA30: 4 | IE30: 1 | IJ30: 5 | IK30: 6 | IV30: 4 | IW30: 1 | IX30: 1 | IY30: 4 | IZ30: 4 | JA30: 4 | JB30: 4 | JC30: 4 | JD30: 4 | JE30: 4 | JF30: 3 | JG30: 4 | JH30: 1 | JI30: 6 | JJ30: 9 | JK30: 5 | JL30: 6 | JN30: 4 | JP30: 1 | JR30: 3 | JS30: 3 | JT30: 2 | JU30: 3
A31: 8pbij40t | B31: iqbcsrl1 | C31: 2023-10-11 19:09:02 | D31: 남 | E31: 54 | F31: 50대 | G31: 50~54세 | H31: 서울 | I31: 서울 | J31: 45~54세 | K31: 수도권 | L31: 남 50대 | M31: 남 50~54세 | N31: 남 45~54세 | O31: 1 | S31: 3 | W31: 45 | X31: 3 | Z31: 1 | AA31: 2 | AB31: 3 | AC31: 4 | AD31: 5 | AJ31: 1 | AK31: 2 | AL31: 3 | AN31: 1 | AO31: 3 | AP31: 2 | AR31: 3 | AS31: 2 | AT31: 1 | AW31: 1 | AX31: 10 | AY31: 2 | AZ31: 5 | BA31: 9 | BD31: 1 | BE31: 7 | BF31: 4 | BH31: 1 | BI31: 3 | BJ31: 5 | BK31: 5 | BL31: 5 | BM31: 5 | BN31: 1 | BO31: 4 | BP31: 2 | BQ31: 3 | BR31: 1 | BU31: 2 | BV31: 3 | BW31: 1 | BY31: 1 | BZ31: 2 | CA31: 3 | CC31: 4 | CD31: 2 | CF31: 30 | CG31: 3 | CH31: 1 | CI31: 1 | CK31: 4 | CL31: 1 | CM31: 2 | CP31: 3 | CR31: 1 | CT31: 3 | CU31: 4 | CV31: 5 | DD31: 3 | DG31: 6 | DL31: 2 | DM31: 2 | DN31: 2 | DO31: 2 | DP31: 4 | DQ31: 1 | DR31: 2 | DT31: 1 | DV31: 1 | DW31: 2 | DZ31: 5 | EA31: 6 | EC31: 8 | ED31: 9 | EJ31: 4 | EK31: 1 | EN31: 4 | ER31: 2 | ES31: 4 | ET31: 2 | EU31: 3 | EV31: 3 | EW31: 4 | EX31: 4 | EY31: 1 | EZ31: 8 | FA31: 7 | FC31: 4 | FD31: 1 | FE31: 45 | FF31: 30 | FG31: 1 | FI31: 1 | FK31: 2 | FM31: 1 | FO31: 1 | FQ31: 1 | FR31: 3 | FW31: 3 | GD31: 2 | GN31: 12 | GP31: 14 | GT31: 18 | GW31: 21 | HA31: 1 | HE31: 5 | HJ31: 1 | HK31: 4 | HL31: 5 | HM31: 2 | HN31: 1 | HX31: 1 | HY31: 2 | IE31: 2 | IO31: 2 | IR31: 5 | IV31: 3 | IW31: 1 | IX31: 3 | IY31: 3 | IZ31: 4 | JA31: 3 | JB31: 3 | JC31: 3 | JD31: 3 | JE31: 3 | JF31: 3 | JG31: 3 | JH31: 1 | JI31: 6 | JJ31: 9 | JK31: 5 | JL31: 3 | JN31: 4 | JP31: 1 | JR31: 2 | JS31: 5 | JT31: 5 | JU31: 2
A32: 8wrr6swc | B32: rilmbrla | C32: 2023-10-11 19:18:33 | D32: 남 | E32: 27 | F32: 20대 | G32: 25~29세 | H32: 서울 | I32: 서울 | J32: 25~34세 | K32: 수도권 | L32: 남 20대 | M32: 남 25~29세 | N32: 남 25~34세 | O32: 1 | R32: 2 | W32: 8 | X32: 3 | Z32: 1 | AB32: 3 | AJ32: 1 | AK32: 3 | AN32: 1 | AO32: 3 | AP32: 4 | AR32: 3 | AS32: 1 | AW32: 2 | AX32: 11 | AY32: 8 | AZ32: 1 | BA32: 9 | BD32: 2 | BE32: 3 | BF32: 10 | BH32: 1 | BI32: 3 | BJ32: 4 | BK32: 4 | BL32: 2 | BM32: 2 | BN32: 4 | BO32: 4 | BP32: 3 | BQ32: 1 | BU32: 1 | BY32: 1 | BZ32: 2 | CC32: 2 | CD32: 3 | CF32: 70 | CG32: 4 | CH32: 1 | CI32: 1 | CK32: 5 | CL32: 2 | CP32: 4 | CR32: 1 | DI32: 8 | DL32: 2 | DM32: 2 | DN32: 2 | DO32: 3 | DP32: 4 | DQ32: 1 | DR32: 2 | DT32: 1 | EC32: 8 | EJ32: 2 | EK32: 1 | EN32: 4 | ER32: 2 | ES32: 2 | ET32: 2 | EU32: 2 | EV32: 2 | EW32: 3 | EX32: 4 | EY32: 4 | EZ32: 5 | FA32: 3 | FC32: 2 | FD32: 1 | FE32: 30 | FF32: 30 | FG32: 1 | FI32: 1 | FK32: 2 | FM32: 2 | FO32: 3 | FQ32: 1 | FR32: 4 | FY32: 5 | GB32: -1 | HE32: 5 | HJ32: 1 | HK32: 4 | HL32: 4 | HM32: 2 | HN32: 2 | HQ32: 3 | HR32: 4 | HS32: 5 | HT32: 6 | HW32: -1 | IV32: 3 | IW32: 1 | IX32: 2 | IY32: 3 | IZ32: 5 | JA32: 4 | JB32: 3 | JC32: 3 | JD32: 3 | JE32: 3 | JF32: 4 | JG32: 4 | JH32: 1 | JI32: 6 | JJ32: 9 | JK32: 1 | JL32: 10 | JN32: 4 | JP32: 2 | JR32: 3 | JS32: 1 | JT32: 1 | JU32: 2
A33: zky6tm8y | B33: zavh47v5 | C33: 2023-10-11 19:29:03 | D33: 여 | E33: 24 | F33: 20대 | G33: 20~24세 | H33: 경기 | I33: 서울 외 수도권 | J33: 15~24세 | K33: 수도권 | L33: 여 20대 | M33: 여 20~24세 | N33: 여 15~24세 | O33: 1 | S33: 3 | W33: 8 | X33: 5 | AA33: 2 | AJ33: 2 | AN33: 1 | AO33: 2 | AP33: 3 | AR33: 1 | AW33: 13 | AX33: 5 | AY33: 9 | BD33: 3 | BE33: 4 | BF33: 2 | BH33: 1 | BI33: 3 | BJ33: 4 | BK33: 2 | BL33: 3 | BM33: 2 | BN33: 1 | BO33: 4 | BP33: 3 | BU33: 1 | BY33: 2 | CC33: 1 | CD33: 2 | CF33: 70 | CG33: 3 | CH33: 1 | CI33: 2 | CK33: 4 | CL33: 2 | CP33: 3 | CR33: 1 | DB33: 1 | DF33: 5 | DI33: 8 | DL33: 1 | DM33: 3 | DN33: 4 | DO33: 4 | DP33: 3 | DQ33: 1 | DR33: 1 | DT33: 4 | DW33: 2 | EF33: 11 | EJ33: 3 | EL33: 2 | EN33: 4 | ER33: 2 | ES33: 3 | ET33: 3 | EU33: 3 | EV33: 4 | EW33: 1 | EX33: 2 | EY33: 6 | EZ33: 4 | FA33: 2 | FC33: 2 | FD33: 1 | FE33: 90 | FF33: 30 | FG33: 1 | FI33: 1 | FK33: 2 | FM33: 1 | FO33: 1 | FQ33: 1 | FR33: 2 | FU33: 1 | FW33: 3 | FX33: 4 | GB33: -1 | GZ33: -1 | HJ33: 1 | HK33: 4 | HL33: 5 | HM33: 2 | HN33: 1 | HW33: -1 | IV33: 2 | IW33: 1 | IX33: 2 | IY33: 4 | IZ33: 5 | JA33: 2 | JB33: 1 | JC33: 1 | JD33: 3 | JE33: 2 | JF33: 5 | JG33: 1 | JH33: 1 | JI33: 6 | JJ33: 2 | JK33: 2 | JL33: 4 | JN33: 9 | JP33: 2 | JR33: 3 | JS33: 2 | JT33: 2 | JU33: 4
A34: jkf2wo0p | B34: z5tlpumy | C34: 2023-10-11 19:06:29 | D34: 여 | E34: 27 | F34: 20대 | G34: 25~29세 | H34: 인천 | I34: 서울 외 수도권 | J34: 25~34세 | K34: 수도권 | L34: 여 20대 | M34: 여 25~29세 | N34: 여 25~34세 | O34: 1 | P34: -1 | W34: 9 | X34: 4 | Z34: 1 | AA34: 2 | AB34: 3 | AJ34: 1 | AN34: 3 | AO34: 1 | AP34: 2 | AR34: 3 | AS34: 1 | AT34: 2 | AW34: 4 | AX34: 2 | AY34: 13 | AZ34: 9 | BA34: 12 | BD34: 4 | BE34: 2 | BF34: 6 | BH34: 1 | BI34: 4 | BJ34: 4 | BK34: 2 | BL34: 2 | BM34: 3 | BN34: 2 | BO34: 4 | BP34: 3 | BQ34: 2 | BU34: 2 | BY34: 2 | CC34: 4 | CD34: 3 | CF34: 60 | CG34: 3 | CH34: 1 | CI34: 1 | CK34: 4 | CL34: 5 | CM34: 2 | CP34: 3 | CR34: 1 | CY34: 8 | DC34: 2 | DD34: 3 | DL34: 1 | DM34: 2 | DN34: 3 | DO34: 3 | DP34: 3 | DQ34: 1 | DR34: 2 | DT34: 1 | DV34: 1 | EJ34: 2 | EN34: 4 | ER34: 3 | ES34: 4 | ET34: 2 | EU34: 2 | EV34: 2 | EW34: 1 | EX34: 4 | EY34: 8 | EZ34: 4 | FA34: 5 | FC34: 3 | FD34: 1 | FE34: 50 | FF34: 30 | FG34: 1 | FI34: 1 | FK34: 2 | FM34: 2 | FO34: 1 | FQ34: 2 | FR34: 2 | FW34: 3 | FX34: 4 | GK34: 9 | GR34: 16 | GT34: 18 | HB34: 2 | HE34: 5 | HJ34: 1 | HK34: 3 | HL34: 3 | HM34: 2 | HN34: 1 | HW34: -1 | IV34: 3 | IW34: 1 | IX34: 4 | IY34: 4 | IZ34: 4 | JA34: 4 | JB34: 4 | JC34: 4 | JD34: 4 | JE34: 4 | JF34: 4 | JG34: 4 | JH34: 1 | JI34: 6 | JJ34: 2 | JK34: 1 | JL34: 7 | JN34: 5 | JP34: 2 | JR34: 3 | JS34: 3 | JT34: 2 | JU34: 3
A35: rbwfwub8 | B35: xkgorar3 | C35: 2023-10-11 19:25:55 | D35: 남 | E35: 29 | F35: 20대 | G35: 25~29세 | H35: 서울 | I35: 서울 | J35: 25~34세 | K35: 수도권 | L35: 남 20대 | M35: 남 25~29세 | N35: 남 25~34세 | O35: 1 | P35: -1 | W35: 40 | X35: 3 | Z35: 1 | AC35: 4 | AJ35: 1 | AK35: 4 | AN35: 1 | AO35: 2 | AR35: 2 | AS35: 3 | AT35: 1 | AW35: 9 | AX35: 8 | AY35: 13 | BD35: 1 | BE35: 6 | BF35: 2 | BH35: 1 | BI35: 1 | BJ35: 4 | BK35: 4 | BL35: 2 | BM35: 2 | BN35: 3 | BO35: 1 | BP35: 4 | BQ35: 3 | BR35: 2 | BU35: 2 | BV35: 1 | BW35: 3 | BX35: 4 | BY35: 1 | BZ35: 2 | CA35: 3 | CB35: 4 | CC35: 4 | CD35: 2 | CF35: 60 | CG35: 4 | CH35: 1 | CI35: 1 | CK35: 1 | CL35: 3 | CM35: 4 | CN35: 5 | CO35: 2 | CP35: 3 | CX35: 7 | CY35: 8 | DC35: 2 | DG35: 6 | DL35: 2 | DM35: 3 | DN35: 4 | DO35: 4 | DP35: 4 | DQ35: 1 | DR35: 1 | DT35: 2 | EC35: 8 | EJ35: 2 | EL35: 2 | ER35: 2 | ES35: 3 | ET35: 2 | EU35: 3 | EV35: 2 | EW35: 3 | EX35: 3 | EY35: 3 | EZ35: 1 | FA35: 9 | FC35: 3 | FD35: 1 | FE35: 60 | FF35: 30 | FG35: 1 | FI35: 1 | FK35: 2 | FM35: 2 | FO35: 2 | FQ35: 2 | FR35: 1 | FW35: 3 | GB35: -1 | HE35: 5 | HJ35: 1 | HK35: 4 | HL35: 4 | HM35: 1 | HN35: 1 | HW35: -1 | IV35: 3 | IW35: 1 | IX35: 2 | IY35: 3 | IZ35: 3 | JA35: 3 | JB35: 3 | JC35: 3 | JD35: 3 | JE35: 3 | JF35: 3 | JG35: 3 | JH35: 1 | JI35: 6 | JJ35: 2 | JK35: 2 | JL35: 8 | JN35: 1 | JP35: 2 | JR35: 3 | JS35: 1 | JT35: 1 | JU35: 2
A36: q69mt5cd | B36: fogz88ir | C36: 2023-10-11 19:07:03 | D36: 남 | E36: 24 | F36: 20대 | G36: 20~24세 | H36: 대전 | I36: 5대광역시 | J36: 15~24세 | K36: 비수도권 | L36: 남 20대 | M36: 남 20~24세 | N36: 남 15~24세 | O36: 1 | U36: 5 | V36: 교대근무 | W36: 48 | X36: 1 | Y36: -1 | AN36: 1 | AO36: 4 | AP36: 5 | AR36: 5 | AS36: 3 | AT36: 6 | AW36: 11 | AX36: 5 | AY36: 6 | AZ36: 8 | BA36: 13 | BD36: 1 | BE36: 6 | BF36: 3 | BH36: 1 | BI36: 4 | BJ36: 3 | BK36: 5 | BL36: 1 | BM36: 1 | BN36: 4 | BO36: 4 | BU36: 1 | BY36: 3 | CC36: 3 | CD36: 3 | CF36: 30 | CG36: 4 | CH36: 1 | CI36: 2 | CK36: 4 | CP36: 3 | CQ36: -1 | DF36: 5 | DI36: 8 | DL36: 2 | DM36: 5 | DN36: 2 | DO36: 4 | DP36: 3 | DQ36: 1 | DR36: 2 | DT36: 2 | EC36: 8 | EJ36: 3 | EN36: 4 | EO36: 5 | ER36: 3 | ES36: 4 | ET36: 4 | EU36: 3 | EV36: 3 | EW36: 1 | EX36: 3 | EY36: 5 | EZ36: 7 | FC36: 3 | FD36: 1 | FE36: 30 | FF36: 30 | FG36: 2 | FI36: 2 | FK36: 1 | FM36: 1 | FO36: 4 | FQ36: 2 | FR36: 2 | FT36: -1 | GQ36: 15 | GR36: 16 | GU36: 19 | GV36: 20 | GW36: 21 | HC36: 3 | HD36: 4 | HJ36: 1 | HK36: 4 | HL36: 4 | HM36: 2 | HN36: 2 | HP36: 2 | HS36: 5 | HW36: -1 | IV36: 4 | IW36: 1 | IX36: 3 | IY36: 3 | IZ36: 4 | JA36: 4 | JB36: 4 | JC36: 3 | JD36: 3 | JE36: 3 | JF36: 2 | JG36: 5 | JH36: 1 | JI36: 5 | JJ36: 7 | JK36: 2 | JL36: 11 | JN36: 12 | JP36: 1 | JR36: 3 | JS36: 1 | JT36: 1 | JU36: 0
A37: 9oxcuc9j | B37: x2yj7zou | C37: 2023-10-11 19:24:32 | D37: 남 | E37: 52 | F37: 50대 | G37: 50~54세 | H37: 경기 | I37: 서울 외 수도권 | J37: 45~54세 | K37: 수도권 | L37: 남 50대 | M37: 남 50~54세 | N37: 남 45~54세 | O37: 1 | S37: 3 | W37: 40 | X37: 5 | Y37: -1 | AN37: 1 | AO37: 2 | AP37: 4 | AR37: 1 | AS37: 6 | AT37: 2 | AW37: 16 | AX37: 1 | AY37: 5 | BD37: 2 | BE37: 6 | BF37: 4 | BH37: 1 | BI37: 2 | BJ37: 4 | BK37: 5 | BL37: 1 | BM37: 4 | BN37: 4 | BO37: 1 | BP37: 4 | BU37: 1 | BV37: 2 | BY37: 2 | BZ37: 1 | CC37: 4 | CD37: 2 | CF37: 5 | CG37: 5 | CH37: 1 | CI37: 1 | CK37: 4 | CL37: 2 | CP37: 4 | CR37: 1 | CU37: 4 | CW37: 6 | DB37: 1 | DD37: 3 | DF37: 5 | DL37: 3 | DM37: 4 | DN37: 5 | DO37: 4 | DP37: 5 | DQ37: 1 | DR37: 2 | DT37: 4 | DV37: 1 | DW37: 2 | DZ37: 5 | EA37: 6 | EC37: 8 | EJ37: 4 | EK37: 1 | EL37: 2 | EM37: 3 | EN37: 4 | EO37: 5 | ER37: 2 | ES37: 4 | ET37: 4 | EU37: 4 | EV37: 4 | EW37: 3 | EX37: 3 | EY37: 9 | EZ37: 2 | FA37: 5 | FC37: 4 | FD37: 1 | FE37: 60 | FF37: 40 | FG37: 1 | FI37: 1 | FK37: 1 | FM37: 1 | FO37: 3 | FQ37: 2 | FR37: 4 | FW37: 3 | FY37: 5 | GC37: 1 | GI37: 7 | GR37: 16 | HA37: 1 | HE37: 5 | HJ37: 1 | HK37: 4 | HL37: 4 | HM37: 2 | HN37: 2 | HO37: 1 | HP37: 2 | HT37: 6 | HX37: 1 | HY37: 2 | IE37: 1 | IG37: 2 | IJ37: 5 | IV37: 4 | IW37: 1 | IX37: 3 | IY37: 4 | IZ37: 4 | JA37: 4 | JB37: 3 | JC37: 3 | JD37: 4 | JE37: 4 | JF37: 4 | JG37: 4 | JH37: 1 | JI37: 6 | JJ37: 9 | JK37: 5 | JL37: 6 | JN37: 7 | JP37: 1 | JR37: 2 | JS37: 6 | JT37: 4 | JU37: 4
A38: 8cu0p6tg | B38: nylgi0n1 | C38: 2023-10-11 19:11:52 | D38: 여 | E38: 44 | F38: 40대 | G38: 40~44세 | H38: 서울 | I38: 서울 | J38: 35~44세 | K38: 수도권 | L38: 여 40대 | M38: 여 40~44세 | N38: 여 35~44세 | O38: 1 | R38: 2 | W38: 40 | X38: 4 | Z38: 1 | AE38: 6 | AJ38: 1 | AK38: 6 | AN38: 1 | AO38: 4 | AR38: 1 | AS38: 4 | AW38: 13 | AX38: 1 | AY38: 8 | AZ38: 10 | BA38: 9 | BD38: 1 | BE38: 9 | BH38: 1 | BI38: 4 | BJ38: 4 | BK38: 3 | BL38: 2 | BM38: 1 | BN38: 1 | BO38: 4 | BP38: 1 | BU38: 1 | BY38: 1 | CC38: 4 | CD38: 4 | CE38: 0 | CF38: 60 | CG38: 4 | CH38: 1 | CI38: 2 | CK38: 1 | CP38: 4 | CR38: 1 | DE38: 4 | DF38: 5 | DH38: 7 | DL38: 3 | DM38: 4 | DN38: 4 | DO38: 3 | DP38: 3 | DQ38: 1 | DR38: 4 | DT38: 4 | DW38: 2 | DZ38: 5 | EF38: 11 | EJ38: 4 | EL38: 2 | EN38: 4 | ER38: 3 | ES38: 4 | ET38: 4 | EU38: 4 | EV38: 4 | EW38: 1 | EX38: 3 | EY38: 5 | EZ38: 2 | FC38: 3 | FD38: 1 | FE38: 120 | FF38: 60 | FG38: 1 | FI38: 1 | FK38: 2 | FM38: 2 | FO38: 2 | FQ38: 1 | FR38: 3 | FU38: 1 | GC38: 1 | GE38: 3 | GK38: 9 | GO38: 13 | GQ38: 15 | GR38: 16 | GT38: 18 | GW38: 21 | HA38: 1 | HC38: 3 | HD38: 4 | HE38: 5 | HJ38: 1 | HK38: 4 | HL38: 3 | HM38: 2 | HN38: 2 | HR38: 4 | HS38: 5 | HT38: 6 | HX38: 1 | IE38: 2 | IN38: 1 | IV38: 3 | IW38: 1 | IX38: 4 | IY38: 4 | IZ38: 4 | JA38: 4 | JB38: 4 | JC38: 4 | JD38: 4 | JE38: 4 | JF38: 4 | JG38: 4 | JH38: 1 | JI38: 6 | JJ38: 2 | JK38: 5 | JL38: 3 | JN38: 1 | JP38: 1 | JR38: 3 | JS38: 6 | JT38: 6 | JU38: 3
A39: fve71oiq | B39: 9rydsiii | C39: 2023-10-11 20:13:12 | D39: 여 | E39: 50 | F39: 50대 | G39: 50~54세 | H39: 서울 | I39: 서울 | J39: 45~54세 | K39: 수도권 | L39: 여 50대 | M39: 여 50~54세 | N39: 여 45~54세 | O39: 1 | Q39: 1 | W39: 36 | X39: 3 | Y39: -1 | AN39: 4 | AR39: 4 | AW39: 3 | AX39: 2 | BD39: 1 | BE39: 4 | BF39: 3 | BH39: 1 | BI39: 3 | BJ39: 2 | BK39: 2 | BL39: 1 | BM39: 1 | BN39: 5 | BO39: 3 | BU39: 2 | BY39: 2 | CC39: 1 | CD39: 1 | CF39: 60 | CG39: 5 | CH39: 1 | CI39: 1 | CK39: 4 | CP39: 3 | CR39: 1 | CT39: 3 | CV39: 5 | DD39: 3 | DL39: 1 | DM39: 4 | DN39: 4 | DO39: 3 | DP39: 4 | DQ39: 1 | DR39: 3 | DT39: 2 | DZ39: 5 | EB39: 7 | EC39: 8 | EF39: 11 | EJ39: 5 | EL39: 2 | ER39: 3 | ES39: 5 | ET39: 5 | EU39: 5 | EV39: 4 | EW39: 3 | EX39: 1 | EY39: 3 | EZ39: 7 | FA39: 6 | FC39: 4 | FD39: 1 | FE39: 30 | FF39: 60 | FG39: 1 | FI39: 1 | FK39: 1 | FM39: 1 | FO39: 3 | FQ39: 1 | FR39: 3 | FW39: 3 | FY39: 5 | GC39: 1 | GR39: 16 | GV39: 20 | HA39: 1 | HE39: 5 | HJ39: 1 | HK39: 4 | HL39: 3 | HM39: 1 | HN39: 2 | HO39: 1 | HQ39: 3 | HX39: 1 | IE39: 3 | IH39: 3 | IQ39: 4 | IV39: 4 | IW39: 1 | IX39: 3 | IY39: 4 | IZ39: 4 | JA39: 4 | JB39: 4 | JC39: 4 | JD39: 4 | JE39: 3 | JF39: 4 | JG39: 4 | JH39: 1 | JI39: 5 | JJ39: 9 | JK39: 4 | JL39: 11 | JN39: 12 | JP39: 4 | JR39: 3 | JS39: 2 | JT39: 2 | JU39: 2
